Internal Server Error: /payment/1/withdraw/request/
"POST /payment/1/withdraw/request/ HTTP/1.1" 500 66
Internal Server Error: /payment/1/withdraw/request/
"POST /payment/1/withdraw/request/ HTTP/1.1" 500 66
Internal Server Error: /payment/1/withdraw/request/
"POST /payment/1/withdraw/request/ HTTP/1.1" 500 66
Internal Server Error: /auth/reset/password
Traceback (most recent call last):
  File "/home/quarjo/pollproject/env/lib/python3.12/site-packages/django/core/handlers/exception.py", line 55, in inner
    response = get_response(request)
               ^^^^^^^^^^^^^^^^^^^^^
  File "/home/quarjo/pollproject/env/lib/python3.12/site-packages/django/utils/deprecation.py", line 131, in __call__
    response = self.process_response(request, response)
               ^^^^^^^^^^^^^^^^^^^^^^^^^^^^^^^^^^^^^^^^
  File "/home/quarjo/pollproject/env/lib/python3.12/site-packages/django/middleware/common.py", line 108, in process_response
    return self.response_redirect_class(self.get_full_path_with_slash(request))
                                        ^^^^^^^^^^^^^^^^^^^^^^^^^^^^^^^^^^^^^^
  File "/home/quarjo/pollproject/env/lib/python3.12/site-packages/django/middleware/common.py", line 87, in get_full_path_with_slash
    raise RuntimeError(
RuntimeError: You called this URL via POST, but the URL doesn't end in a slash and you have APPEND_SLASH set. Django can't redirect to the slash URL while maintaining POST data. Change your form to point to localhost:8000/auth/reset/password/ (note the trailing slash), or set APPEND_SLASH=False in your Django settings.
"POST /auth/reset/password HTTP/1.1" 500 73182
Internal Server Error: /auth/reset/password
Traceback (most recent call last):
  File "/home/quarjo/pollproject/env/lib/python3.12/site-packages/django/core/handlers/exception.py", line 55, in inner
    response = get_response(request)
               ^^^^^^^^^^^^^^^^^^^^^
  File "/home/quarjo/pollproject/env/lib/python3.12/site-packages/django/utils/deprecation.py", line 131, in __call__
    response = self.process_response(request, response)
               ^^^^^^^^^^^^^^^^^^^^^^^^^^^^^^^^^^^^^^^^
  File "/home/quarjo/pollproject/env/lib/python3.12/site-packages/django/middleware/common.py", line 108, in process_response
    return self.response_redirect_class(self.get_full_path_with_slash(request))
                                        ^^^^^^^^^^^^^^^^^^^^^^^^^^^^^^^^^^^^^^
  File "/home/quarjo/pollproject/env/lib/python3.12/site-packages/django/middleware/common.py", line 87, in get_full_path_with_slash
    raise RuntimeError(
RuntimeError: You called this URL via POST, but the URL doesn't end in a slash and you have APPEND_SLASH set. Django can't redirect to the slash URL while maintaining POST data. Change your form to point to localhost:8000/auth/reset/password/ (note the trailing slash), or set APPEND_SLASH=False in your Django settings.
"POST /auth/reset/password HTTP/1.1" 500 73182
Internal Server Error: /auth/update/
Traceback (most recent call last):
  File "/home/quarjo/pollproject/env/lib/python3.12/site-packages/django/core/handlers/exception.py", line 55, in inner
    response = get_response(request)
               ^^^^^^^^^^^^^^^^^^^^^
  File "/home/quarjo/pollproject/env/lib/python3.12/site-packages/django/core/handlers/base.py", line 197, in _get_response
    response = wrapped_callback(request, *callback_args, **callback_kwargs)
               ^^^^^^^^^^^^^^^^^^^^^^^^^^^^^^^^^^^^^^^^^^^^^^^^^^^^^^^^^^^^
  File "/home/quarjo/pollproject/env/lib/python3.12/site-packages/django/views/decorators/csrf.py", line 65, in _view_wrapper
    return view_func(request, *args, **kwargs)
           ^^^^^^^^^^^^^^^^^^^^^^^^^^^^^^^^^^^
  File "/home/quarjo/pollproject/env/lib/python3.12/site-packages/django/views/generic/base.py", line 104, in view
    return self.dispatch(request, *args, **kwargs)
           ^^^^^^^^^^^^^^^^^^^^^^^^^^^^^^^^^^^^^^^
  File "/home/quarjo/pollproject/env/lib/python3.12/site-packages/rest_framework/views.py", line 509, in dispatch
    response = self.handle_exception(exc)
               ^^^^^^^^^^^^^^^^^^^^^^^^^^
  File "/home/quarjo/pollproject/env/lib/python3.12/site-packages/rest_framework/views.py", line 469, in handle_exception
    self.raise_uncaught_exception(exc)
  File "/home/quarjo/pollproject/env/lib/python3.12/site-packages/rest_framework/views.py", line 480, in raise_uncaught_exception
    raise exc
  File "/home/quarjo/pollproject/env/lib/python3.12/site-packages/rest_framework/views.py", line 506, in dispatch
    response = handler(request, *args, **kwargs)
               ^^^^^^^^^^^^^^^^^^^^^^^^^^^^^^^^^
  File "/home/quarjo/pollproject/authentication/views.py", line 68, in patch
    serializer.save()
  File "/home/quarjo/pollproject/env/lib/python3.12/site-packages/rest_framework/serializers.py", line 203, in save
    self.instance = self.update(self.instance, validated_data)
                    ^^^^^^^^^^^^^^^^^^^^^^^^^^^^^^^^^^^^^^^^^^
  File "/home/quarjo/pollproject/authentication/serializers.py", line 48, in update
    raise ValidationError("Account number cannot be changed.")
django.core.exceptions.ValidationError: ['Account number cannot be changed.']
"PATCH /auth/update/ HTTP/1.1" 500 104918
Internal Server Error: /auth/update/
Traceback (most recent call last):
  File "/home/quarjo/pollproject/env/lib/python3.12/site-packages/django/core/handlers/exception.py", line 55, in inner
    response = get_response(request)
               ^^^^^^^^^^^^^^^^^^^^^
  File "/home/quarjo/pollproject/env/lib/python3.12/site-packages/django/core/handlers/base.py", line 197, in _get_response
    response = wrapped_callback(request, *callback_args, **callback_kwargs)
               ^^^^^^^^^^^^^^^^^^^^^^^^^^^^^^^^^^^^^^^^^^^^^^^^^^^^^^^^^^^^
  File "/home/quarjo/pollproject/env/lib/python3.12/site-packages/django/views/decorators/csrf.py", line 65, in _view_wrapper
    return view_func(request, *args, **kwargs)
           ^^^^^^^^^^^^^^^^^^^^^^^^^^^^^^^^^^^
  File "/home/quarjo/pollproject/env/lib/python3.12/site-packages/django/views/generic/base.py", line 104, in view
    return self.dispatch(request, *args, **kwargs)
           ^^^^^^^^^^^^^^^^^^^^^^^^^^^^^^^^^^^^^^^
  File "/home/quarjo/pollproject/env/lib/python3.12/site-packages/rest_framework/views.py", line 509, in dispatch
    response = self.handle_exception(exc)
               ^^^^^^^^^^^^^^^^^^^^^^^^^^
  File "/home/quarjo/pollproject/env/lib/python3.12/site-packages/rest_framework/views.py", line 469, in handle_exception
    self.raise_uncaught_exception(exc)
  File "/home/quarjo/pollproject/env/lib/python3.12/site-packages/rest_framework/views.py", line 480, in raise_uncaught_exception
    raise exc
  File "/home/quarjo/pollproject/env/lib/python3.12/site-packages/rest_framework/views.py", line 506, in dispatch
    response = handler(request, *args, **kwargs)
               ^^^^^^^^^^^^^^^^^^^^^^^^^^^^^^^^^
  File "/home/quarjo/pollproject/authentication/views.py", line 68, in patch
    serializer.save()
  File "/home/quarjo/pollproject/env/lib/python3.12/site-packages/rest_framework/serializers.py", line 203, in save
    self.instance = self.update(self.instance, validated_data)
                    ^^^^^^^^^^^^^^^^^^^^^^^^^^^^^^^^^^^^^^^^^^
  File "/home/quarjo/pollproject/authentication/serializers.py", line 48, in update
    raise ValidationError("Account number cannot be changed.")
django.core.exceptions.ValidationError: ['Account number cannot be changed.']
"PATCH /auth/update/ HTTP/1.1" 500 104918
Internal Server Error: /auth/update/
Traceback (most recent call last):
  File "/home/quarjo/pollproject/env/lib/python3.12/site-packages/django/core/handlers/exception.py", line 55, in inner
    response = get_response(request)
               ^^^^^^^^^^^^^^^^^^^^^
  File "/home/quarjo/pollproject/env/lib/python3.12/site-packages/django/core/handlers/base.py", line 197, in _get_response
    response = wrapped_callback(request, *callback_args, **callback_kwargs)
               ^^^^^^^^^^^^^^^^^^^^^^^^^^^^^^^^^^^^^^^^^^^^^^^^^^^^^^^^^^^^
  File "/home/quarjo/pollproject/env/lib/python3.12/site-packages/django/views/decorators/csrf.py", line 65, in _view_wrapper
    return view_func(request, *args, **kwargs)
           ^^^^^^^^^^^^^^^^^^^^^^^^^^^^^^^^^^^
  File "/home/quarjo/pollproject/env/lib/python3.12/site-packages/django/views/generic/base.py", line 104, in view
    return self.dispatch(request, *args, **kwargs)
           ^^^^^^^^^^^^^^^^^^^^^^^^^^^^^^^^^^^^^^^
  File "/home/quarjo/pollproject/env/lib/python3.12/site-packages/rest_framework/views.py", line 509, in dispatch
    response = self.handle_exception(exc)
               ^^^^^^^^^^^^^^^^^^^^^^^^^^
  File "/home/quarjo/pollproject/env/lib/python3.12/site-packages/rest_framework/views.py", line 469, in handle_exception
    self.raise_uncaught_exception(exc)
  File "/home/quarjo/pollproject/env/lib/python3.12/site-packages/rest_framework/views.py", line 480, in raise_uncaught_exception
    raise exc
  File "/home/quarjo/pollproject/env/lib/python3.12/site-packages/rest_framework/views.py", line 506, in dispatch
    response = handler(request, *args, **kwargs)
               ^^^^^^^^^^^^^^^^^^^^^^^^^^^^^^^^^
  File "/home/quarjo/pollproject/authentication/views.py", line 68, in patch
    serializer.save()
  File "/home/quarjo/pollproject/env/lib/python3.12/site-packages/rest_framework/serializers.py", line 203, in save
    self.instance = self.update(self.instance, validated_data)
                    ^^^^^^^^^^^^^^^^^^^^^^^^^^^^^^^^^^^^^^^^^^
  File "/home/quarjo/pollproject/authentication/serializers.py", line 43, in update
    raise ValidationError("Account number cannot be changed.")
django.core.exceptions.ValidationError: ['Account number cannot be changed.']
"PATCH /auth/update/ HTTP/1.1" 500 104941
Internal Server Error: /auth/update/
Traceback (most recent call last):
  File "/home/quarjo/pollproject/env/lib/python3.12/site-packages/django/core/handlers/exception.py", line 55, in inner
    response = get_response(request)
               ^^^^^^^^^^^^^^^^^^^^^
  File "/home/quarjo/pollproject/env/lib/python3.12/site-packages/django/core/handlers/base.py", line 197, in _get_response
    response = wrapped_callback(request, *callback_args, **callback_kwargs)
               ^^^^^^^^^^^^^^^^^^^^^^^^^^^^^^^^^^^^^^^^^^^^^^^^^^^^^^^^^^^^
  File "/home/quarjo/pollproject/env/lib/python3.12/site-packages/django/views/decorators/csrf.py", line 65, in _view_wrapper
    return view_func(request, *args, **kwargs)
           ^^^^^^^^^^^^^^^^^^^^^^^^^^^^^^^^^^^
  File "/home/quarjo/pollproject/env/lib/python3.12/site-packages/django/views/generic/base.py", line 104, in view
    return self.dispatch(request, *args, **kwargs)
           ^^^^^^^^^^^^^^^^^^^^^^^^^^^^^^^^^^^^^^^
  File "/home/quarjo/pollproject/env/lib/python3.12/site-packages/rest_framework/views.py", line 509, in dispatch
    response = self.handle_exception(exc)
               ^^^^^^^^^^^^^^^^^^^^^^^^^^
  File "/home/quarjo/pollproject/env/lib/python3.12/site-packages/rest_framework/views.py", line 469, in handle_exception
    self.raise_uncaught_exception(exc)
  File "/home/quarjo/pollproject/env/lib/python3.12/site-packages/rest_framework/views.py", line 480, in raise_uncaught_exception
    raise exc
  File "/home/quarjo/pollproject/env/lib/python3.12/site-packages/rest_framework/views.py", line 506, in dispatch
    response = handler(request, *args, **kwargs)
               ^^^^^^^^^^^^^^^^^^^^^^^^^^^^^^^^^
  File "/home/quarjo/pollproject/authentication/views.py", line 68, in patch
    serializer.save()
  File "/home/quarjo/pollproject/env/lib/python3.12/site-packages/rest_framework/serializers.py", line 203, in save
    self.instance = self.update(self.instance, validated_data)
                    ^^^^^^^^^^^^^^^^^^^^^^^^^^^^^^^^^^^^^^^^^^
  File "/home/quarjo/pollproject/authentication/serializers.py", line 43, in update
    raise ValidationError("Account number cannot be changed.")
django.core.exceptions.ValidationError: ['Account number cannot be changed.']
"PATCH /auth/update/ HTTP/1.1" 500 104945
Internal Server Error: /auth/update/
Traceback (most recent call last):
  File "/home/quarjo/pollproject/env/lib/python3.12/site-packages/django/core/handlers/exception.py", line 55, in inner
    response = get_response(request)
               ^^^^^^^^^^^^^^^^^^^^^
  File "/home/quarjo/pollproject/env/lib/python3.12/site-packages/django/core/handlers/base.py", line 197, in _get_response
    response = wrapped_callback(request, *callback_args, **callback_kwargs)
               ^^^^^^^^^^^^^^^^^^^^^^^^^^^^^^^^^^^^^^^^^^^^^^^^^^^^^^^^^^^^
  File "/home/quarjo/pollproject/env/lib/python3.12/site-packages/django/views/decorators/csrf.py", line 65, in _view_wrapper
    return view_func(request, *args, **kwargs)
           ^^^^^^^^^^^^^^^^^^^^^^^^^^^^^^^^^^^
  File "/home/quarjo/pollproject/env/lib/python3.12/site-packages/django/views/generic/base.py", line 104, in view
    return self.dispatch(request, *args, **kwargs)
           ^^^^^^^^^^^^^^^^^^^^^^^^^^^^^^^^^^^^^^^
  File "/home/quarjo/pollproject/env/lib/python3.12/site-packages/rest_framework/views.py", line 509, in dispatch
    response = self.handle_exception(exc)
               ^^^^^^^^^^^^^^^^^^^^^^^^^^
  File "/home/quarjo/pollproject/env/lib/python3.12/site-packages/rest_framework/views.py", line 469, in handle_exception
    self.raise_uncaught_exception(exc)
  File "/home/quarjo/pollproject/env/lib/python3.12/site-packages/rest_framework/views.py", line 480, in raise_uncaught_exception
    raise exc
  File "/home/quarjo/pollproject/env/lib/python3.12/site-packages/rest_framework/views.py", line 506, in dispatch
    response = handler(request, *args, **kwargs)
               ^^^^^^^^^^^^^^^^^^^^^^^^^^^^^^^^^
  File "/home/quarjo/pollproject/authentication/views.py", line 68, in patch
    serializer.save()
  File "/home/quarjo/pollproject/env/lib/python3.12/site-packages/rest_framework/serializers.py", line 203, in save
    self.instance = self.update(self.instance, validated_data)
                    ^^^^^^^^^^^^^^^^^^^^^^^^^^^^^^^^^^^^^^^^^^
  File "/home/quarjo/pollproject/authentication/serializers.py", line 46, in update
    raise ValidationError("Account number cannot be changed.")
django.core.exceptions.ValidationError: ['Account number cannot be changed.']
"PATCH /auth/update/ HTTP/1.1" 500 104783
Internal Server Error: /payment/history/
Traceback (most recent call last):
  File "/home/quarjo/pollproject/env/lib/python3.12/site-packages/django/core/handlers/exception.py", line 55, in inner
    response = get_response(request)
               ^^^^^^^^^^^^^^^^^^^^^
  File "/home/quarjo/pollproject/env/lib/python3.12/site-packages/django/core/handlers/base.py", line 197, in _get_response
    response = wrapped_callback(request, *callback_args, **callback_kwargs)
               ^^^^^^^^^^^^^^^^^^^^^^^^^^^^^^^^^^^^^^^^^^^^^^^^^^^^^^^^^^^^
  File "/home/quarjo/pollproject/env/lib/python3.12/site-packages/django/views/decorators/csrf.py", line 65, in _view_wrapper
    return view_func(request, *args, **kwargs)
           ^^^^^^^^^^^^^^^^^^^^^^^^^^^^^^^^^^^
  File "/home/quarjo/pollproject/env/lib/python3.12/site-packages/django/views/generic/base.py", line 104, in view
    return self.dispatch(request, *args, **kwargs)
           ^^^^^^^^^^^^^^^^^^^^^^^^^^^^^^^^^^^^^^^
  File "/home/quarjo/pollproject/env/lib/python3.12/site-packages/rest_framework/views.py", line 509, in dispatch
    response = self.handle_exception(exc)
               ^^^^^^^^^^^^^^^^^^^^^^^^^^
  File "/home/quarjo/pollproject/env/lib/python3.12/site-packages/rest_framework/views.py", line 469, in handle_exception
    self.raise_uncaught_exception(exc)
  File "/home/quarjo/pollproject/env/lib/python3.12/site-packages/rest_framework/views.py", line 480, in raise_uncaught_exception
    raise exc
  File "/home/quarjo/pollproject/env/lib/python3.12/site-packages/rest_framework/views.py", line 506, in dispatch
    response = handler(request, *args, **kwargs)
               ^^^^^^^^^^^^^^^^^^^^^^^^^^^^^^^^^
  File "/home/quarjo/pollproject/payment/views.py", line 548, in get
    return paginator.get_paginated_response(serializer.data)
           ^^^^^^^^^^^^^^^^^^^^^^^^^^^^^^^^^^^^^^^^^^^^^^^^^
  File "/home/quarjo/pollproject/env/lib/python3.12/site-packages/rest_framework/pagination.py", line 232, in get_paginated_response
    'count': self.page.paginator.count,
             ^^^^^^^^^
AttributeError: 'PageNumberPagination' object has no attribute 'page'
"GET /payment/history/ HTTP/1.1" 500 100398
Internal Server Error: /payment/history/
Traceback (most recent call last):
  File "/home/quarjo/pollproject/env/lib/python3.12/site-packages/django/core/handlers/exception.py", line 55, in inner
    response = get_response(request)
               ^^^^^^^^^^^^^^^^^^^^^
  File "/home/quarjo/pollproject/env/lib/python3.12/site-packages/django/core/handlers/base.py", line 197, in _get_response
    response = wrapped_callback(request, *callback_args, **callback_kwargs)
               ^^^^^^^^^^^^^^^^^^^^^^^^^^^^^^^^^^^^^^^^^^^^^^^^^^^^^^^^^^^^
  File "/home/quarjo/pollproject/env/lib/python3.12/site-packages/django/views/decorators/csrf.py", line 65, in _view_wrapper
    return view_func(request, *args, **kwargs)
           ^^^^^^^^^^^^^^^^^^^^^^^^^^^^^^^^^^^
  File "/home/quarjo/pollproject/env/lib/python3.12/site-packages/django/views/generic/base.py", line 104, in view
    return self.dispatch(request, *args, **kwargs)
           ^^^^^^^^^^^^^^^^^^^^^^^^^^^^^^^^^^^^^^^
  File "/home/quarjo/pollproject/env/lib/python3.12/site-packages/rest_framework/views.py", line 509, in dispatch
    response = self.handle_exception(exc)
               ^^^^^^^^^^^^^^^^^^^^^^^^^^
  File "/home/quarjo/pollproject/env/lib/python3.12/site-packages/rest_framework/views.py", line 469, in handle_exception
    self.raise_uncaught_exception(exc)
  File "/home/quarjo/pollproject/env/lib/python3.12/site-packages/rest_framework/views.py", line 480, in raise_uncaught_exception
    raise exc
  File "/home/quarjo/pollproject/env/lib/python3.12/site-packages/rest_framework/views.py", line 506, in dispatch
    response = handler(request, *args, **kwargs)
               ^^^^^^^^^^^^^^^^^^^^^^^^^^^^^^^^^
  File "/home/quarjo/pollproject/payment/views.py", line 527, in get
    return paginator.get_paginated_response(serializer.data)
           ^^^^^^^^^^^^^^^^^^^^^^^^^^^^^^^^^^^^^^^^^^^^^^^^^
  File "/home/quarjo/pollproject/env/lib/python3.12/site-packages/rest_framework/pagination.py", line 232, in get_paginated_response
    'count': self.page.paginator.count,
             ^^^^^^^^^
AttributeError: 'PageNumberPagination' object has no attribute 'page'
"GET /payment/history/ HTTP/1.1" 500 100398
Internal Server Error: /payment/history/
Traceback (most recent call last):
  File "/home/quarjo/pollproject/env/lib/python3.12/site-packages/django/core/handlers/exception.py", line 55, in inner
    response = get_response(request)
               ^^^^^^^^^^^^^^^^^^^^^
  File "/home/quarjo/pollproject/env/lib/python3.12/site-packages/django/core/handlers/base.py", line 197, in _get_response
    response = wrapped_callback(request, *callback_args, **callback_kwargs)
               ^^^^^^^^^^^^^^^^^^^^^^^^^^^^^^^^^^^^^^^^^^^^^^^^^^^^^^^^^^^^
  File "/home/quarjo/pollproject/env/lib/python3.12/site-packages/django/views/decorators/csrf.py", line 65, in _view_wrapper
    return view_func(request, *args, **kwargs)
           ^^^^^^^^^^^^^^^^^^^^^^^^^^^^^^^^^^^
  File "/home/quarjo/pollproject/env/lib/python3.12/site-packages/django/views/generic/base.py", line 104, in view
    return self.dispatch(request, *args, **kwargs)
           ^^^^^^^^^^^^^^^^^^^^^^^^^^^^^^^^^^^^^^^
  File "/home/quarjo/pollproject/env/lib/python3.12/site-packages/rest_framework/views.py", line 509, in dispatch
    response = self.handle_exception(exc)
               ^^^^^^^^^^^^^^^^^^^^^^^^^^
  File "/home/quarjo/pollproject/env/lib/python3.12/site-packages/rest_framework/views.py", line 469, in handle_exception
    self.raise_uncaught_exception(exc)
  File "/home/quarjo/pollproject/env/lib/python3.12/site-packages/rest_framework/views.py", line 480, in raise_uncaught_exception
    raise exc
  File "/home/quarjo/pollproject/env/lib/python3.12/site-packages/rest_framework/views.py", line 506, in dispatch
    response = handler(request, *args, **kwargs)
               ^^^^^^^^^^^^^^^^^^^^^^^^^^^^^^^^^
  File "/home/quarjo/pollproject/payment/views.py", line 526, in get
    return paginator.get_paginated_response(serializer.data)
           ^^^^^^^^^^^^^^^^^^^^^^^^^^^^^^^^^^^^^^^^^^^^^^^^^
  File "/home/quarjo/pollproject/env/lib/python3.12/site-packages/rest_framework/pagination.py", line 232, in get_paginated_response
    'count': self.page.paginator.count,
             ^^^^^^^^^
AttributeError: 'PageNumberPagination' object has no attribute 'page'
"GET /payment/history/ HTTP/1.1" 500 100398
Internal Server Error: /token/refresh
Traceback (most recent call last):
  File "/home/quarjo/pollproject/env/lib/python3.12/site-packages/django/core/handlers/exception.py", line 55, in inner
    response = get_response(request)
               ^^^^^^^^^^^^^^^^^^^^^
  File "/home/quarjo/pollproject/env/lib/python3.12/site-packages/django/utils/deprecation.py", line 131, in __call__
    response = self.process_response(request, response)
               ^^^^^^^^^^^^^^^^^^^^^^^^^^^^^^^^^^^^^^^^
  File "/home/quarjo/pollproject/env/lib/python3.12/site-packages/django/middleware/common.py", line 108, in process_response
    return self.response_redirect_class(self.get_full_path_with_slash(request))
                                        ^^^^^^^^^^^^^^^^^^^^^^^^^^^^^^^^^^^^^^
  File "/home/quarjo/pollproject/env/lib/python3.12/site-packages/django/middleware/common.py", line 87, in get_full_path_with_slash
    raise RuntimeError(
RuntimeError: You called this URL via POST, but the URL doesn't end in a slash and you have APPEND_SLASH set. Django can't redirect to the slash URL while maintaining POST data. Change your form to point to 127.0.0.1:8000/token/refresh/ (note the trailing slash), or set APPEND_SLASH=False in your Django settings.
"POST /token/refresh HTTP/1.1" 500 72415
Internal Server Error: /auth/reset/password/MQ/cgnmrv-6429bfa9244e80d162fae498051d5acd/
Traceback (most recent call last):
  File "/home/quarjo/pollproject/env/lib/python3.12/site-packages/django/core/handlers/exception.py", line 55, in inner
    response = get_response(request)
               ^^^^^^^^^^^^^^^^^^^^^
  File "/home/quarjo/pollproject/env/lib/python3.12/site-packages/django/core/handlers/base.py", line 197, in _get_response
    response = wrapped_callback(request, *callback_args, **callback_kwargs)
               ^^^^^^^^^^^^^^^^^^^^^^^^^^^^^^^^^^^^^^^^^^^^^^^^^^^^^^^^^^^^
  File "/home/quarjo/pollproject/env/lib/python3.12/site-packages/django/views/decorators/csrf.py", line 65, in _view_wrapper
    return view_func(request, *args, **kwargs)
           ^^^^^^^^^^^^^^^^^^^^^^^^^^^^^^^^^^^
  File "/home/quarjo/pollproject/env/lib/python3.12/site-packages/django/views/generic/base.py", line 104, in view
    return self.dispatch(request, *args, **kwargs)
           ^^^^^^^^^^^^^^^^^^^^^^^^^^^^^^^^^^^^^^^
  File "/home/quarjo/pollproject/env/lib/python3.12/site-packages/rest_framework/views.py", line 511, in dispatch
    self.response = self.finalize_response(request, response, *args, **kwargs)
                    ^^^^^^^^^^^^^^^^^^^^^^^^^^^^^^^^^^^^^^^^^^^^^^^^^^^^^^^^^^
  File "/home/quarjo/pollproject/env/lib/python3.12/site-packages/rest_framework/views.py", line 423, in finalize_response
    assert isinstance(response, HttpResponseBase), (
           ^^^^^^^^^^^^^^^^^^^^^^^^^^^^^^^^^^^^^^
AssertionError: Expected a `Response`, `HttpResponse` or `StreamingHttpResponse` to be returned from the view, but received a `<class 'NoneType'>`
"POST /auth/reset/password/MQ/cgnmrv-6429bfa9244e80d162fae498051d5acd/ HTTP/1.1" 500 19577
Internal Server Error: /auth/reset/password/MQ/cgnmrv-6429bfa9244e80d162fae498051d5acd/
Traceback (most recent call last):
  File "/home/quarjo/pollproject/env/lib/python3.12/site-packages/django/core/handlers/exception.py", line 55, in inner
    response = get_response(request)
               ^^^^^^^^^^^^^^^^^^^^^
  File "/home/quarjo/pollproject/env/lib/python3.12/site-packages/django/core/handlers/base.py", line 197, in _get_response
    response = wrapped_callback(request, *callback_args, **callback_kwargs)
               ^^^^^^^^^^^^^^^^^^^^^^^^^^^^^^^^^^^^^^^^^^^^^^^^^^^^^^^^^^^^
  File "/home/quarjo/pollproject/env/lib/python3.12/site-packages/django/views/decorators/csrf.py", line 65, in _view_wrapper
    return view_func(request, *args, **kwargs)
           ^^^^^^^^^^^^^^^^^^^^^^^^^^^^^^^^^^^
  File "/home/quarjo/pollproject/env/lib/python3.12/site-packages/django/views/generic/base.py", line 104, in view
    return self.dispatch(request, *args, **kwargs)
           ^^^^^^^^^^^^^^^^^^^^^^^^^^^^^^^^^^^^^^^
  File "/home/quarjo/pollproject/env/lib/python3.12/site-packages/rest_framework/views.py", line 511, in dispatch
    self.response = self.finalize_response(request, response, *args, **kwargs)
                    ^^^^^^^^^^^^^^^^^^^^^^^^^^^^^^^^^^^^^^^^^^^^^^^^^^^^^^^^^^
  File "/home/quarjo/pollproject/env/lib/python3.12/site-packages/rest_framework/views.py", line 423, in finalize_response
    assert isinstance(response, HttpResponseBase), (
           ^^^^^^^^^^^^^^^^^^^^^^^^^^^^^^^^^^^^^^
AssertionError: Expected a `Response`, `HttpResponse` or `StreamingHttpResponse` to be returned from the view, but received a `<class 'NoneType'>`
"POST /auth/reset/password/MQ/cgnmrv-6429bfa9244e80d162fae498051d5acd/ HTTP/1.1" 500 19577
Internal Server Error: /auth/reset/password/MQ/cgnmrv-6429bfa9244e80d162fae498051d5acd/
Traceback (most recent call last):
  File "/home/quarjo/pollproject/env/lib/python3.12/site-packages/django/core/handlers/exception.py", line 55, in inner
    response = get_response(request)
               ^^^^^^^^^^^^^^^^^^^^^
  File "/home/quarjo/pollproject/env/lib/python3.12/site-packages/django/core/handlers/base.py", line 197, in _get_response
    response = wrapped_callback(request, *callback_args, **callback_kwargs)
               ^^^^^^^^^^^^^^^^^^^^^^^^^^^^^^^^^^^^^^^^^^^^^^^^^^^^^^^^^^^^
  File "/home/quarjo/pollproject/env/lib/python3.12/site-packages/django/views/decorators/csrf.py", line 65, in _view_wrapper
    return view_func(request, *args, **kwargs)
           ^^^^^^^^^^^^^^^^^^^^^^^^^^^^^^^^^^^
  File "/home/quarjo/pollproject/env/lib/python3.12/site-packages/django/views/generic/base.py", line 104, in view
    return self.dispatch(request, *args, **kwargs)
           ^^^^^^^^^^^^^^^^^^^^^^^^^^^^^^^^^^^^^^^
  File "/home/quarjo/pollproject/env/lib/python3.12/site-packages/rest_framework/views.py", line 511, in dispatch
    self.response = self.finalize_response(request, response, *args, **kwargs)
                    ^^^^^^^^^^^^^^^^^^^^^^^^^^^^^^^^^^^^^^^^^^^^^^^^^^^^^^^^^^
  File "/home/quarjo/pollproject/env/lib/python3.12/site-packages/rest_framework/views.py", line 423, in finalize_response
    assert isinstance(response, HttpResponseBase), (
           ^^^^^^^^^^^^^^^^^^^^^^^^^^^^^^^^^^^^^^
AssertionError: Expected a `Response`, `HttpResponse` or `StreamingHttpResponse` to be returned from the view, but received a `<class 'NoneType'>`
"POST /auth/reset/password/MQ/cgnmrv-6429bfa9244e80d162fae498051d5acd/ HTTP/1.1" 500 19577
Internal Server Error: /polls/create/
Traceback (most recent call last):
  File "/home/quarjo/pollproject/env/lib/python3.12/site-packages/django/core/handlers/exception.py", line 55, in inner
    response = get_response(request)
               ^^^^^^^^^^^^^^^^^^^^^
  File "/home/quarjo/pollproject/env/lib/python3.12/site-packages/django/core/handlers/base.py", line 197, in _get_response
    response = wrapped_callback(request, *callback_args, **callback_kwargs)
               ^^^^^^^^^^^^^^^^^^^^^^^^^^^^^^^^^^^^^^^^^^^^^^^^^^^^^^^^^^^^
  File "/home/quarjo/pollproject/env/lib/python3.12/site-packages/django/views/decorators/csrf.py", line 65, in _view_wrapper
    return view_func(request, *args, **kwargs)
           ^^^^^^^^^^^^^^^^^^^^^^^^^^^^^^^^^^^
  File "/home/quarjo/pollproject/env/lib/python3.12/site-packages/django/views/generic/base.py", line 104, in view
    return self.dispatch(request, *args, **kwargs)
           ^^^^^^^^^^^^^^^^^^^^^^^^^^^^^^^^^^^^^^^
  File "/home/quarjo/pollproject/env/lib/python3.12/site-packages/rest_framework/views.py", line 509, in dispatch
    response = self.handle_exception(exc)
               ^^^^^^^^^^^^^^^^^^^^^^^^^^
  File "/home/quarjo/pollproject/env/lib/python3.12/site-packages/rest_framework/views.py", line 469, in handle_exception
    self.raise_uncaught_exception(exc)
  File "/home/quarjo/pollproject/env/lib/python3.12/site-packages/rest_framework/views.py", line 480, in raise_uncaught_exception
    raise exc
  File "/home/quarjo/pollproject/env/lib/python3.12/site-packages/rest_framework/views.py", line 506, in dispatch
    response = handler(request, *args, **kwargs)
               ^^^^^^^^^^^^^^^^^^^^^^^^^^^^^^^^^
  File "/home/quarjo/pollproject/poll/views.py", line 37, in post
    if serializer.is_valid():
       ^^^^^^^^^^^^^^^^^^^^^
  File "/home/quarjo/pollproject/env/lib/python3.12/site-packages/rest_framework/serializers.py", line 223, in is_valid
    self._validated_data = self.run_validation(self.initial_data)
                           ^^^^^^^^^^^^^^^^^^^^^^^^^^^^^^^^^^^^^^
  File "/home/quarjo/pollproject/env/lib/python3.12/site-packages/rest_framework/serializers.py", line 442, in run_validation
    value = self.to_internal_value(data)
            ^^^^^^^^^^^^^^^^^^^^^^^^^^^^
  File "/home/quarjo/pollproject/env/lib/python3.12/site-packages/rest_framework/serializers.py", line 499, in to_internal_value
    validated_value = field.run_validation(primitive_value)
                      ^^^^^^^^^^^^^^^^^^^^^^^^^^^^^^^^^^^^^
  File "/home/quarjo/pollproject/env/lib/python3.12/site-packages/rest_framework/serializers.py", line 634, in run_validation
    value = self.to_internal_value(data)
            ^^^^^^^^^^^^^^^^^^^^^^^^^^^^
  File "/home/quarjo/pollproject/env/lib/python3.12/site-packages/rest_framework/serializers.py", line 693, in to_internal_value
    validated = self.run_child_validation(item)
                ^^^^^^^^^^^^^^^^^^^^^^^^^^^^^^^
  File "/home/quarjo/pollproject/env/lib/python3.12/site-packages/rest_framework/serializers.py", line 653, in run_child_validation
    return self.child.run_validation(data)
           ^^^^^^^^^^^^^^^^^^^^^^^^^^^^^^^
  File "/home/quarjo/pollproject/env/lib/python3.12/site-packages/rest_framework/serializers.py", line 442, in run_validation
    value = self.to_internal_value(data)
            ^^^^^^^^^^^^^^^^^^^^^^^^^^^^
  File "/home/quarjo/pollproject/env/lib/python3.12/site-packages/rest_framework/serializers.py", line 501, in to_internal_value
    validated_value = validate_method(validated_value)
                      ^^^^^^^^^^^^^^^^^^^^^^^^^^^^^^^^
  File "/home/quarjo/pollproject/poll/serializers.py", line 17, in validate_image
    if not image.name.endswith(('.jpg', '.jpeg', '.png')):
           ^^^^^^^^^^
AttributeError: 'NoneType' object has no attribute 'name'
"POST /polls/create/ HTTP/1.1" 500 150097
Internal Server Error: /polls/create/
Traceback (most recent call last):
  File "/home/quarjo/pollproject/env/lib/python3.12/site-packages/django/core/handlers/exception.py", line 55, in inner
    response = get_response(request)
               ^^^^^^^^^^^^^^^^^^^^^
  File "/home/quarjo/pollproject/env/lib/python3.12/site-packages/django/core/handlers/base.py", line 197, in _get_response
    response = wrapped_callback(request, *callback_args, **callback_kwargs)
               ^^^^^^^^^^^^^^^^^^^^^^^^^^^^^^^^^^^^^^^^^^^^^^^^^^^^^^^^^^^^
  File "/home/quarjo/pollproject/env/lib/python3.12/site-packages/django/views/decorators/csrf.py", line 65, in _view_wrapper
    return view_func(request, *args, **kwargs)
           ^^^^^^^^^^^^^^^^^^^^^^^^^^^^^^^^^^^
  File "/home/quarjo/pollproject/env/lib/python3.12/site-packages/django/views/generic/base.py", line 104, in view
    return self.dispatch(request, *args, **kwargs)
           ^^^^^^^^^^^^^^^^^^^^^^^^^^^^^^^^^^^^^^^
  File "/home/quarjo/pollproject/env/lib/python3.12/site-packages/rest_framework/views.py", line 509, in dispatch
    response = self.handle_exception(exc)
               ^^^^^^^^^^^^^^^^^^^^^^^^^^
  File "/home/quarjo/pollproject/env/lib/python3.12/site-packages/rest_framework/views.py", line 469, in handle_exception
    self.raise_uncaught_exception(exc)
  File "/home/quarjo/pollproject/env/lib/python3.12/site-packages/rest_framework/views.py", line 480, in raise_uncaught_exception
    raise exc
  File "/home/quarjo/pollproject/env/lib/python3.12/site-packages/rest_framework/views.py", line 506, in dispatch
    response = handler(request, *args, **kwargs)
               ^^^^^^^^^^^^^^^^^^^^^^^^^^^^^^^^^
  File "/home/quarjo/pollproject/poll/views.py", line 37, in post
    if serializer.is_valid():
       ^^^^^^^^^^^^^^^^^^^^^
  File "/home/quarjo/pollproject/env/lib/python3.12/site-packages/rest_framework/serializers.py", line 223, in is_valid
    self._validated_data = self.run_validation(self.initial_data)
                           ^^^^^^^^^^^^^^^^^^^^^^^^^^^^^^^^^^^^^^
  File "/home/quarjo/pollproject/env/lib/python3.12/site-packages/rest_framework/serializers.py", line 442, in run_validation
    value = self.to_internal_value(data)
            ^^^^^^^^^^^^^^^^^^^^^^^^^^^^
  File "/home/quarjo/pollproject/env/lib/python3.12/site-packages/rest_framework/serializers.py", line 499, in to_internal_value
    validated_value = field.run_validation(primitive_value)
                      ^^^^^^^^^^^^^^^^^^^^^^^^^^^^^^^^^^^^^
  File "/home/quarjo/pollproject/env/lib/python3.12/site-packages/rest_framework/serializers.py", line 634, in run_validation
    value = self.to_internal_value(data)
            ^^^^^^^^^^^^^^^^^^^^^^^^^^^^
  File "/home/quarjo/pollproject/env/lib/python3.12/site-packages/rest_framework/serializers.py", line 693, in to_internal_value
    validated = self.run_child_validation(item)
                ^^^^^^^^^^^^^^^^^^^^^^^^^^^^^^^
  File "/home/quarjo/pollproject/env/lib/python3.12/site-packages/rest_framework/serializers.py", line 653, in run_child_validation
    return self.child.run_validation(data)
           ^^^^^^^^^^^^^^^^^^^^^^^^^^^^^^^
  File "/home/quarjo/pollproject/env/lib/python3.12/site-packages/rest_framework/serializers.py", line 442, in run_validation
    value = self.to_internal_value(data)
            ^^^^^^^^^^^^^^^^^^^^^^^^^^^^
  File "/home/quarjo/pollproject/env/lib/python3.12/site-packages/rest_framework/serializers.py", line 501, in to_internal_value
    validated_value = validate_method(validated_value)
                      ^^^^^^^^^^^^^^^^^^^^^^^^^^^^^^^^
  File "/home/quarjo/pollproject/poll/serializers.py", line 17, in validate_image
    if not image.name.endswith(('.jpg', '.jpeg', '.png')):
           ^^^^^^^^^^
AttributeError: 'NoneType' object has no attribute 'name'
"POST /polls/create/ HTTP/1.1" 500 150097
Internal Server Error: /polls/create/
Traceback (most recent call last):
  File "/home/quarjo/pollproject/env/lib/python3.12/site-packages/django/core/handlers/exception.py", line 55, in inner
    response = get_response(request)
               ^^^^^^^^^^^^^^^^^^^^^
  File "/home/quarjo/pollproject/env/lib/python3.12/site-packages/django/core/handlers/base.py", line 197, in _get_response
    response = wrapped_callback(request, *callback_args, **callback_kwargs)
               ^^^^^^^^^^^^^^^^^^^^^^^^^^^^^^^^^^^^^^^^^^^^^^^^^^^^^^^^^^^^
  File "/home/quarjo/pollproject/env/lib/python3.12/site-packages/django/views/decorators/csrf.py", line 65, in _view_wrapper
    return view_func(request, *args, **kwargs)
           ^^^^^^^^^^^^^^^^^^^^^^^^^^^^^^^^^^^
  File "/home/quarjo/pollproject/env/lib/python3.12/site-packages/django/views/generic/base.py", line 104, in view
    return self.dispatch(request, *args, **kwargs)
           ^^^^^^^^^^^^^^^^^^^^^^^^^^^^^^^^^^^^^^^
  File "/home/quarjo/pollproject/env/lib/python3.12/site-packages/rest_framework/views.py", line 509, in dispatch
    response = self.handle_exception(exc)
               ^^^^^^^^^^^^^^^^^^^^^^^^^^
  File "/home/quarjo/pollproject/env/lib/python3.12/site-packages/rest_framework/views.py", line 469, in handle_exception
    self.raise_uncaught_exception(exc)
  File "/home/quarjo/pollproject/env/lib/python3.12/site-packages/rest_framework/views.py", line 480, in raise_uncaught_exception
    raise exc
  File "/home/quarjo/pollproject/env/lib/python3.12/site-packages/rest_framework/views.py", line 506, in dispatch
    response = handler(request, *args, **kwargs)
               ^^^^^^^^^^^^^^^^^^^^^^^^^^^^^^^^^
  File "/home/quarjo/pollproject/poll/views.py", line 37, in post
    if serializer.is_valid():
       ^^^^^^^^^^^^^^^^^^^^^
  File "/home/quarjo/pollproject/env/lib/python3.12/site-packages/rest_framework/serializers.py", line 223, in is_valid
    self._validated_data = self.run_validation(self.initial_data)
                           ^^^^^^^^^^^^^^^^^^^^^^^^^^^^^^^^^^^^^^
  File "/home/quarjo/pollproject/env/lib/python3.12/site-packages/rest_framework/serializers.py", line 442, in run_validation
    value = self.to_internal_value(data)
            ^^^^^^^^^^^^^^^^^^^^^^^^^^^^
  File "/home/quarjo/pollproject/env/lib/python3.12/site-packages/rest_framework/serializers.py", line 499, in to_internal_value
    validated_value = field.run_validation(primitive_value)
                      ^^^^^^^^^^^^^^^^^^^^^^^^^^^^^^^^^^^^^
  File "/home/quarjo/pollproject/env/lib/python3.12/site-packages/rest_framework/serializers.py", line 634, in run_validation
    value = self.to_internal_value(data)
            ^^^^^^^^^^^^^^^^^^^^^^^^^^^^
  File "/home/quarjo/pollproject/env/lib/python3.12/site-packages/rest_framework/serializers.py", line 693, in to_internal_value
    validated = self.run_child_validation(item)
                ^^^^^^^^^^^^^^^^^^^^^^^^^^^^^^^
  File "/home/quarjo/pollproject/env/lib/python3.12/site-packages/rest_framework/serializers.py", line 653, in run_child_validation
    return self.child.run_validation(data)
           ^^^^^^^^^^^^^^^^^^^^^^^^^^^^^^^
  File "/home/quarjo/pollproject/env/lib/python3.12/site-packages/rest_framework/serializers.py", line 442, in run_validation
    value = self.to_internal_value(data)
            ^^^^^^^^^^^^^^^^^^^^^^^^^^^^
  File "/home/quarjo/pollproject/env/lib/python3.12/site-packages/rest_framework/serializers.py", line 501, in to_internal_value
    validated_value = validate_method(validated_value)
                      ^^^^^^^^^^^^^^^^^^^^^^^^^^^^^^^^
  File "/home/quarjo/pollproject/poll/serializers.py", line 17, in validate_image
    if not image.endswith(('.jpg', '.jpeg', '.png')):
           ^^^^^^^^^^^^^^
AttributeError: 'NoneType' object has no attribute 'endswith'
"POST /polls/create/ HTTP/1.1" 500 150111
Internal Server Error: /polls/create/
Traceback (most recent call last):
  File "/home/quarjo/pollproject/env/lib/python3.12/site-packages/django/core/handlers/exception.py", line 55, in inner
    response = get_response(request)
               ^^^^^^^^^^^^^^^^^^^^^
  File "/home/quarjo/pollproject/env/lib/python3.12/site-packages/django/core/handlers/base.py", line 197, in _get_response
    response = wrapped_callback(request, *callback_args, **callback_kwargs)
               ^^^^^^^^^^^^^^^^^^^^^^^^^^^^^^^^^^^^^^^^^^^^^^^^^^^^^^^^^^^^
  File "/home/quarjo/pollproject/env/lib/python3.12/site-packages/django/views/decorators/csrf.py", line 65, in _view_wrapper
    return view_func(request, *args, **kwargs)
           ^^^^^^^^^^^^^^^^^^^^^^^^^^^^^^^^^^^
  File "/home/quarjo/pollproject/env/lib/python3.12/site-packages/django/views/generic/base.py", line 104, in view
    return self.dispatch(request, *args, **kwargs)
           ^^^^^^^^^^^^^^^^^^^^^^^^^^^^^^^^^^^^^^^
  File "/home/quarjo/pollproject/env/lib/python3.12/site-packages/rest_framework/views.py", line 509, in dispatch
    response = self.handle_exception(exc)
               ^^^^^^^^^^^^^^^^^^^^^^^^^^
  File "/home/quarjo/pollproject/env/lib/python3.12/site-packages/rest_framework/views.py", line 469, in handle_exception
    self.raise_uncaught_exception(exc)
  File "/home/quarjo/pollproject/env/lib/python3.12/site-packages/rest_framework/views.py", line 480, in raise_uncaught_exception
    raise exc
  File "/home/quarjo/pollproject/env/lib/python3.12/site-packages/rest_framework/views.py", line 506, in dispatch
    response = handler(request, *args, **kwargs)
               ^^^^^^^^^^^^^^^^^^^^^^^^^^^^^^^^^
  File "/home/quarjo/pollproject/poll/views.py", line 37, in post
    if serializer.is_valid():
       ^^^^^^^^^^^^^^^^^^^^^
  File "/home/quarjo/pollproject/env/lib/python3.12/site-packages/rest_framework/serializers.py", line 223, in is_valid
    self._validated_data = self.run_validation(self.initial_data)
                           ^^^^^^^^^^^^^^^^^^^^^^^^^^^^^^^^^^^^^^
  File "/home/quarjo/pollproject/env/lib/python3.12/site-packages/rest_framework/serializers.py", line 442, in run_validation
    value = self.to_internal_value(data)
            ^^^^^^^^^^^^^^^^^^^^^^^^^^^^
  File "/home/quarjo/pollproject/env/lib/python3.12/site-packages/rest_framework/serializers.py", line 499, in to_internal_value
    validated_value = field.run_validation(primitive_value)
                      ^^^^^^^^^^^^^^^^^^^^^^^^^^^^^^^^^^^^^
  File "/home/quarjo/pollproject/env/lib/python3.12/site-packages/rest_framework/serializers.py", line 634, in run_validation
    value = self.to_internal_value(data)
            ^^^^^^^^^^^^^^^^^^^^^^^^^^^^
  File "/home/quarjo/pollproject/env/lib/python3.12/site-packages/rest_framework/serializers.py", line 693, in to_internal_value
    validated = self.run_child_validation(item)
                ^^^^^^^^^^^^^^^^^^^^^^^^^^^^^^^
  File "/home/quarjo/pollproject/env/lib/python3.12/site-packages/rest_framework/serializers.py", line 653, in run_child_validation
    return self.child.run_validation(data)
           ^^^^^^^^^^^^^^^^^^^^^^^^^^^^^^^
  File "/home/quarjo/pollproject/env/lib/python3.12/site-packages/rest_framework/serializers.py", line 442, in run_validation
    value = self.to_internal_value(data)
            ^^^^^^^^^^^^^^^^^^^^^^^^^^^^
  File "/home/quarjo/pollproject/env/lib/python3.12/site-packages/rest_framework/serializers.py", line 501, in to_internal_value
    validated_value = validate_method(validated_value)
                      ^^^^^^^^^^^^^^^^^^^^^^^^^^^^^^^^
  File "/home/quarjo/pollproject/poll/serializers.py", line 20, in validate_image
    if image.size > 3 * 1024 * 1024:
       ^^^^^^^^^^
AttributeError: 'NoneType' object has no attribute 'size'
"POST /polls/create/ HTTP/1.1" 500 149936
Internal Server Error: /polls/update/2/
Traceback (most recent call last):
  File "/home/quarjo/pollproject/env/lib/python3.12/site-packages/django/core/handlers/exception.py", line 55, in inner
    response = get_response(request)
               ^^^^^^^^^^^^^^^^^^^^^
  File "/home/quarjo/pollproject/env/lib/python3.12/site-packages/django/core/handlers/base.py", line 197, in _get_response
    response = wrapped_callback(request, *callback_args, **callback_kwargs)
               ^^^^^^^^^^^^^^^^^^^^^^^^^^^^^^^^^^^^^^^^^^^^^^^^^^^^^^^^^^^^
  File "/home/quarjo/pollproject/env/lib/python3.12/site-packages/django/views/decorators/csrf.py", line 65, in _view_wrapper
    return view_func(request, *args, **kwargs)
           ^^^^^^^^^^^^^^^^^^^^^^^^^^^^^^^^^^^
  File "/home/quarjo/pollproject/env/lib/python3.12/site-packages/django/views/generic/base.py", line 104, in view
    return self.dispatch(request, *args, **kwargs)
           ^^^^^^^^^^^^^^^^^^^^^^^^^^^^^^^^^^^^^^^
  File "/home/quarjo/pollproject/env/lib/python3.12/site-packages/rest_framework/views.py", line 509, in dispatch
    response = self.handle_exception(exc)
               ^^^^^^^^^^^^^^^^^^^^^^^^^^
  File "/home/quarjo/pollproject/env/lib/python3.12/site-packages/rest_framework/views.py", line 469, in handle_exception
    self.raise_uncaught_exception(exc)
  File "/home/quarjo/pollproject/env/lib/python3.12/site-packages/rest_framework/views.py", line 480, in raise_uncaught_exception
    raise exc
  File "/home/quarjo/pollproject/env/lib/python3.12/site-packages/rest_framework/views.py", line 506, in dispatch
    response = handler(request, *args, **kwargs)
               ^^^^^^^^^^^^^^^^^^^^^^^^^^^^^^^^^
  File "/home/quarjo/pollproject/env/lib/python3.12/site-packages/rest_framework/generics.py", line 233, in patch
    return self.partial_update(request, *args, **kwargs)
           ^^^^^^^^^^^^^^^^^^^^^^^^^^^^^^^^^^^^^^^^^^^^^
  File "/home/quarjo/pollproject/poll/views.py", line 174, in partial_update
    return self.update(request, *args, **kwargs)
           ^^^^^^^^^^^^^^^^^^^^^^^^^^^^^^^^^^^^^
  File "/home/quarjo/pollproject/env/lib/python3.12/site-packages/rest_framework/mixins.py", line 67, in update
    serializer.is_valid(raise_exception=True)
  File "/home/quarjo/pollproject/env/lib/python3.12/site-packages/rest_framework/serializers.py", line 223, in is_valid
    self._validated_data = self.run_validation(self.initial_data)
                           ^^^^^^^^^^^^^^^^^^^^^^^^^^^^^^^^^^^^^^
  File "/home/quarjo/pollproject/env/lib/python3.12/site-packages/rest_framework/serializers.py", line 442, in run_validation
    value = self.to_internal_value(data)
            ^^^^^^^^^^^^^^^^^^^^^^^^^^^^
  File "/home/quarjo/pollproject/env/lib/python3.12/site-packages/rest_framework/serializers.py", line 495, in to_internal_value
    for field in fields:
                 ^^^^^^
  File "/home/quarjo/pollproject/env/lib/python3.12/site-packages/rest_framework/serializers.py", line 378, in _writable_fields
    for field in self.fields.values():
                 ^^^^^^^^^^^
  File "/home/quarjo/pollproject/env/lib/python3.12/site-packages/django/utils/functional.py", line 47, in __get__
    res = instance.__dict__[self.name] = self.func(instance)
                                         ^^^^^^^^^^^^^^^^^^^
  File "/home/quarjo/pollproject/env/lib/python3.12/site-packages/rest_framework/serializers.py", line 372, in fields
    for key, value in self.get_fields().items():
                      ^^^^^^^^^^^^^^^^^
  File "/home/quarjo/pollproject/env/lib/python3.12/site-packages/rest_framework/serializers.py", line 1103, in get_fields
    field_class, field_kwargs = self.build_field(
                                ^^^^^^^^^^^^^^^^^
  File "/home/quarjo/pollproject/env/lib/python3.12/site-packages/rest_framework/serializers.py", line 1249, in build_field
    return self.build_unknown_field(field_name, model_class)
           ^^^^^^^^^^^^^^^^^^^^^^^^^^^^^^^^^^^^^^^^^^^^^^^^^
  File "/home/quarjo/pollproject/env/lib/python3.12/site-packages/rest_framework/serializers.py", line 1367, in build_unknown_field
    raise ImproperlyConfigured(
django.core.exceptions.ImproperlyConfigured: Field name `image` is not valid for model `Poll` in `poll.serializers.UpdatePollSerializer`.
"PATCH /polls/update/2/ HTTP/1.1" 500 156019
Internal Server Error: /admin/login/
Traceback (most recent call last):
  File "/home/quarjo/pollproject/env/lib/python3.12/site-packages/django_redis/cache.py", line 29, in _decorator
    return method(self, *args, **kwargs)
           ^^^^^^^^^^^^^^^^^^^^^^^^^^^^^
  File "/home/quarjo/pollproject/env/lib/python3.12/site-packages/django_redis/cache.py", line 138, in has_key
    return self.client.has_key(*args, **kwargs)
           ^^^^^^^^^^^^^^^^^^^^^^^^^^^^^^^^^^^^
  File "/home/quarjo/pollproject/env/lib/python3.12/site-packages/django_redis/client/default.py", line 670, in has_key
    raise ConnectionInterrupted(connection=client) from e
django_redis.exceptions.ConnectionInterrupted: Redis ConnectionError: Error 111 connecting to 127.0.0.1:6379. Connection refused.

During handling of the above exception, another exception occurred:

Traceback (most recent call last):
  File "/home/quarjo/pollproject/env/lib/python3.12/site-packages/django/core/handlers/exception.py", line 55, in inner
    response = get_response(request)
               ^^^^^^^^^^^^^^^^^^^^^
  File "/home/quarjo/pollproject/env/lib/python3.12/site-packages/django/core/handlers/base.py", line 197, in _get_response
    response = wrapped_callback(request, *callback_args, **callback_kwargs)
               ^^^^^^^^^^^^^^^^^^^^^^^^^^^^^^^^^^^^^^^^^^^^^^^^^^^^^^^^^^^^
  File "/home/quarjo/pollproject/env/lib/python3.12/site-packages/django/utils/decorators.py", line 48, in _wrapper
    return bound_method(*args, **kwargs)
           ^^^^^^^^^^^^^^^^^^^^^^^^^^^^^
  File "/home/quarjo/pollproject/env/lib/python3.12/site-packages/django/views/decorators/cache.py", line 80, in _view_wrapper
    response = view_func(request, *args, **kwargs)
               ^^^^^^^^^^^^^^^^^^^^^^^^^^^^^^^^^^^
  File "/home/quarjo/pollproject/env/lib/python3.12/site-packages/django/contrib/admin/sites.py", line 444, in login
    return LoginView.as_view(**defaults)(request)
           ^^^^^^^^^^^^^^^^^^^^^^^^^^^^^^^^^^^^^^
  File "/home/quarjo/pollproject/env/lib/python3.12/site-packages/django/views/generic/base.py", line 104, in view
    return self.dispatch(request, *args, **kwargs)
           ^^^^^^^^^^^^^^^^^^^^^^^^^^^^^^^^^^^^^^^
  File "/home/quarjo/pollproject/env/lib/python3.12/site-packages/django/utils/decorators.py", line 48, in _wrapper
    return bound_method(*args, **kwargs)
           ^^^^^^^^^^^^^^^^^^^^^^^^^^^^^
  File "/home/quarjo/pollproject/env/lib/python3.12/site-packages/django/utils/decorators.py", line 48, in _wrapper
    return bound_method(*args, **kwargs)
           ^^^^^^^^^^^^^^^^^^^^^^^^^^^^^
  File "/home/quarjo/pollproject/env/lib/python3.12/site-packages/django/views/decorators/debug.py", line 143, in sensitive_post_parameters_wrapper
    return view(request, *args, **kwargs)
           ^^^^^^^^^^^^^^^^^^^^^^^^^^^^^^
  File "/home/quarjo/pollproject/env/lib/python3.12/site-packages/django/utils/decorators.py", line 48, in _wrapper
    return bound_method(*args, **kwargs)
           ^^^^^^^^^^^^^^^^^^^^^^^^^^^^^
  File "/home/quarjo/pollproject/env/lib/python3.12/site-packages/django/utils/decorators.py", line 188, in _view_wrapper
    result = _process_exception(request, e)
             ^^^^^^^^^^^^^^^^^^^^^^^^^^^^^^
  File "/home/quarjo/pollproject/env/lib/python3.12/site-packages/django/utils/decorators.py", line 186, in _view_wrapper
    response = view_func(request, *args, **kwargs)
               ^^^^^^^^^^^^^^^^^^^^^^^^^^^^^^^^^^^
  File "/home/quarjo/pollproject/env/lib/python3.12/site-packages/django/utils/decorators.py", line 48, in _wrapper
    return bound_method(*args, **kwargs)
           ^^^^^^^^^^^^^^^^^^^^^^^^^^^^^
  File "/home/quarjo/pollproject/env/lib/python3.12/site-packages/django/views/decorators/cache.py", line 80, in _view_wrapper
    response = view_func(request, *args, **kwargs)
               ^^^^^^^^^^^^^^^^^^^^^^^^^^^^^^^^^^^
  File "/home/quarjo/pollproject/env/lib/python3.12/site-packages/django/contrib/auth/views.py", line 89, in dispatch
    return super().dispatch(request, *args, **kwargs)
           ^^^^^^^^^^^^^^^^^^^^^^^^^^^^^^^^^^^^^^^^^^
  File "/home/quarjo/pollproject/env/lib/python3.12/site-packages/django/views/generic/base.py", line 143, in dispatch
    return handler(request, *args, **kwargs)
           ^^^^^^^^^^^^^^^^^^^^^^^^^^^^^^^^^
  File "/home/quarjo/pollproject/env/lib/python3.12/site-packages/django/views/generic/edit.py", line 151, in post
    return self.form_valid(form)
           ^^^^^^^^^^^^^^^^^^^^^
  File "/home/quarjo/pollproject/env/lib/python3.12/site-packages/django/contrib/auth/views.py", line 108, in form_valid
    auth_login(self.request, form.get_user())
  File "/home/quarjo/pollproject/env/lib/python3.12/site-packages/django/contrib/auth/__init__.py", line 126, in login
    request.session.cycle_key()
  File "/home/quarjo/pollproject/env/lib/python3.12/site-packages/django/contrib/sessions/backends/base.py", line 432, in cycle_key
    self.create()
  File "/home/quarjo/pollproject/env/lib/python3.12/site-packages/django/contrib/sessions/backends/cache.py", line 55, in create
    self._session_key = self._get_new_session_key()
                        ^^^^^^^^^^^^^^^^^^^^^^^^^^^
  File "/home/quarjo/pollproject/env/lib/python3.12/site-packages/django/contrib/sessions/backends/base.py", line 196, in _get_new_session_key
    if not self.exists(session_key):
           ^^^^^^^^^^^^^^^^^^^^^^^^
  File "/home/quarjo/pollproject/env/lib/python3.12/site-packages/django/contrib/sessions/backends/cache.py", line 117, in exists
    bool(session_key) and (self.cache_key_prefix + session_key) in self._cache
                          ^^^^^^^^^^^^^^^^^^^^^^^^^^^^^^^^^^^^^^^^^^^^^^^^^^^^
  File "/home/quarjo/pollproject/env/lib/python3.12/site-packages/django/core/cache/backends/base.py", line 300, in __contains__
    return self.has_key(key)
           ^^^^^^^^^^^^^^^^^
  File "/home/quarjo/pollproject/env/lib/python3.12/site-packages/django_redis/cache.py", line 36, in _decorator
    raise e.__cause__
  File "/home/quarjo/pollproject/env/lib/python3.12/site-packages/django_redis/client/default.py", line 668, in has_key
    return client.exists(key) == 1
           ^^^^^^^^^^^^^^^^^^
  File "/home/quarjo/pollproject/env/lib/python3.12/site-packages/redis/commands/core.py", line 1729, in exists
    return self.execute_command("EXISTS", *names, keys=names)
           ^^^^^^^^^^^^^^^^^^^^^^^^^^^^^^^^^^^^^^^^^^^^^^^^^^
  File "/home/quarjo/pollproject/env/lib/python3.12/site-packages/redis/client.py", line 559, in execute_command
    return self._execute_command(*args, **options)
           ^^^^^^^^^^^^^^^^^^^^^^^^^^^^^^^^^^^^^^^
  File "/home/quarjo/pollproject/env/lib/python3.12/site-packages/redis/client.py", line 565, in _execute_command
    conn = self.connection or pool.get_connection(command_name, **options)
                              ^^^^^^^^^^^^^^^^^^^^^^^^^^^^^^^^^^^^^^^^^^^^
  File "/home/quarjo/pollproject/env/lib/python3.12/site-packages/redis/connection.py", line 1422, in get_connection
    connection.connect()
  File "/home/quarjo/pollproject/env/lib/python3.12/site-packages/redis/connection.py", line 363, in connect
    raise ConnectionError(self._error_message(e))
redis.exceptions.ConnectionError: Error 111 connecting to 127.0.0.1:6379. Connection refused.
"POST /admin/login/?next=/admin/ HTTP/1.1" 500 217097
Internal Server Error: /polls/create/
Traceback (most recent call last):
  File "/home/quarjo/pollproject/env/lib/python3.12/site-packages/django/core/handlers/exception.py", line 55, in inner
    response = get_response(request)
               ^^^^^^^^^^^^^^^^^^^^^
  File "/home/quarjo/pollproject/env/lib/python3.12/site-packages/django/core/handlers/base.py", line 197, in _get_response
    response = wrapped_callback(request, *callback_args, **callback_kwargs)
               ^^^^^^^^^^^^^^^^^^^^^^^^^^^^^^^^^^^^^^^^^^^^^^^^^^^^^^^^^^^^
  File "/home/quarjo/pollproject/env/lib/python3.12/site-packages/django/views/decorators/csrf.py", line 65, in _view_wrapper
    return view_func(request, *args, **kwargs)
           ^^^^^^^^^^^^^^^^^^^^^^^^^^^^^^^^^^^
  File "/home/quarjo/pollproject/env/lib/python3.12/site-packages/django/views/generic/base.py", line 104, in view
    return self.dispatch(request, *args, **kwargs)
           ^^^^^^^^^^^^^^^^^^^^^^^^^^^^^^^^^^^^^^^
  File "/home/quarjo/pollproject/env/lib/python3.12/site-packages/rest_framework/views.py", line 509, in dispatch
    response = self.handle_exception(exc)
               ^^^^^^^^^^^^^^^^^^^^^^^^^^
  File "/home/quarjo/pollproject/env/lib/python3.12/site-packages/rest_framework/views.py", line 469, in handle_exception
    self.raise_uncaught_exception(exc)
  File "/home/quarjo/pollproject/env/lib/python3.12/site-packages/rest_framework/views.py", line 480, in raise_uncaught_exception
    raise exc
  File "/home/quarjo/pollproject/env/lib/python3.12/site-packages/rest_framework/views.py", line 506, in dispatch
    response = handler(request, *args, **kwargs)
               ^^^^^^^^^^^^^^^^^^^^^^^^^^^^^^^^^
  File "/home/quarjo/pollproject/poll/views.py", line 53, in post
    "download_voter_codes": reverse('download_voter_codes', args=[poll.id]),
                            ^^^^^^^^^^^^^^^^^^^^^^^^^^^^^^^^^^^^^^^^^^^^^^^
  File "/home/quarjo/pollproject/env/lib/python3.12/site-packages/django/urls/base.py", line 88, in reverse
    return resolver._reverse_with_prefix(view, prefix, *args, **kwargs)
           ^^^^^^^^^^^^^^^^^^^^^^^^^^^^^^^^^^^^^^^^^^^^^^^^^^^^^^^^^^^^
  File "/home/quarjo/pollproject/env/lib/python3.12/site-packages/django/urls/resolvers.py", line 831, in _reverse_with_prefix
    raise NoReverseMatch(msg)
django.urls.exceptions.NoReverseMatch: Reverse for 'download_voter_codes' not found. 'download_voter_codes' is not a valid view function or pattern name.
"POST /polls/create/ HTTP/1.1" 500 110323
Internal Server Error: /polls/contestants/
Traceback (most recent call last):
  File "/home/quarjo/pollproject/env/lib/python3.12/site-packages/django/core/handlers/exception.py", line 55, in inner
    response = get_response(request)
               ^^^^^^^^^^^^^^^^^^^^^
  File "/home/quarjo/pollproject/env/lib/python3.12/site-packages/django/core/handlers/base.py", line 197, in _get_response
    response = wrapped_callback(request, *callback_args, **callback_kwargs)
               ^^^^^^^^^^^^^^^^^^^^^^^^^^^^^^^^^^^^^^^^^^^^^^^^^^^^^^^^^^^^
  File "/home/quarjo/pollproject/env/lib/python3.12/site-packages/django/views/decorators/csrf.py", line 65, in _view_wrapper
    return view_func(request, *args, **kwargs)
           ^^^^^^^^^^^^^^^^^^^^^^^^^^^^^^^^^^^
  File "/home/quarjo/pollproject/env/lib/python3.12/site-packages/django/views/generic/base.py", line 104, in view
    return self.dispatch(request, *args, **kwargs)
           ^^^^^^^^^^^^^^^^^^^^^^^^^^^^^^^^^^^^^^^
  File "/home/quarjo/pollproject/env/lib/python3.12/site-packages/rest_framework/views.py", line 509, in dispatch
    response = self.handle_exception(exc)
               ^^^^^^^^^^^^^^^^^^^^^^^^^^
  File "/home/quarjo/pollproject/env/lib/python3.12/site-packages/rest_framework/views.py", line 469, in handle_exception
    self.raise_uncaught_exception(exc)
  File "/home/quarjo/pollproject/env/lib/python3.12/site-packages/rest_framework/views.py", line 480, in raise_uncaught_exception
    raise exc
  File "/home/quarjo/pollproject/env/lib/python3.12/site-packages/rest_framework/views.py", line 506, in dispatch
    response = handler(request, *args, **kwargs)
               ^^^^^^^^^^^^^^^^^^^^^^^^^^^^^^^^^
TypeError: ContestantDetails.get() missing 1 required positional argument: 'poll_id'
"GET /polls/contestants/ HTTP/1.1" 500 91118
