Internal Server Error: /payment/poll/undefined/link/
Traceback (most recent call last):
  File "/home/quarjo/pollproject/env/lib/python3.12/site-packages/django/db/models/fields/__init__.py", line 2123, in get_prep_value
    return int(value)
           ^^^^^^^^^^
ValueError: invalid literal for int() with base 10: 'undefined'

The above exception was the direct cause of the following exception:

Traceback (most recent call last):
  File "/home/quarjo/pollproject/env/lib/python3.12/site-packages/django/core/handlers/exception.py", line 55, in inner
    response = get_response(request)
               ^^^^^^^^^^^^^^^^^^^^^
  File "/home/quarjo/pollproject/env/lib/python3.12/site-packages/django/core/handlers/base.py", line 197, in _get_response
    response = wrapped_callback(request, *callback_args, **callback_kwargs)
               ^^^^^^^^^^^^^^^^^^^^^^^^^^^^^^^^^^^^^^^^^^^^^^^^^^^^^^^^^^^^
  File "/home/quarjo/pollproject/env/lib/python3.12/site-packages/django/views/decorators/csrf.py", line 65, in _view_wrapper
    return view_func(request, *args, **kwargs)
           ^^^^^^^^^^^^^^^^^^^^^^^^^^^^^^^^^^^
  File "/home/quarjo/pollproject/env/lib/python3.12/site-packages/django/views/generic/base.py", line 104, in view
    return self.dispatch(request, *args, **kwargs)
           ^^^^^^^^^^^^^^^^^^^^^^^^^^^^^^^^^^^^^^^
  File "/home/quarjo/pollproject/env/lib/python3.12/site-packages/rest_framework/views.py", line 509, in dispatch
    response = self.handle_exception(exc)
               ^^^^^^^^^^^^^^^^^^^^^^^^^^
  File "/home/quarjo/pollproject/env/lib/python3.12/site-packages/rest_framework/views.py", line 469, in handle_exception
    self.raise_uncaught_exception(exc)
  File "/home/quarjo/pollproject/env/lib/python3.12/site-packages/rest_framework/views.py", line 480, in raise_uncaught_exception
    raise exc
  File "/home/quarjo/pollproject/env/lib/python3.12/site-packages/rest_framework/views.py", line 506, in dispatch
    response = handler(request, *args, **kwargs)
               ^^^^^^^^^^^^^^^^^^^^^^^^^^^^^^^^^
  File "/home/quarjo/pollproject/payment/views.py", line 149, in get
    poll = get_object_or_404(Poll, id=poll_id)
           ^^^^^^^^^^^^^^^^^^^^^^^^^^^^^^^^^^^
  File "/home/quarjo/pollproject/env/lib/python3.12/site-packages/django/shortcuts.py", line 86, in get_object_or_404
    return queryset.get(*args, **kwargs)
           ^^^^^^^^^^^^^^^^^^^^^^^^^^^^^
  File "/home/quarjo/pollproject/env/lib/python3.12/site-packages/django/db/models/query.py", line 635, in get
    clone = self._chain() if self.query.combinator else self.filter(*args, **kwargs)
                                                        ^^^^^^^^^^^^^^^^^^^^^^^^^^^^
  File "/home/quarjo/pollproject/env/lib/python3.12/site-packages/django/db/models/query.py", line 1476, in filter
    return self._filter_or_exclude(False, args, kwargs)
           ^^^^^^^^^^^^^^^^^^^^^^^^^^^^^^^^^^^^^^^^^^^^
  File "/home/quarjo/pollproject/env/lib/python3.12/site-packages/django/db/models/query.py", line 1494, in _filter_or_exclude
    clone._filter_or_exclude_inplace(negate, args, kwargs)
  File "/home/quarjo/pollproject/env/lib/python3.12/site-packages/django/db/models/query.py", line 1501, in _filter_or_exclude_inplace
    self._query.add_q(Q(*args, **kwargs))
  File "/home/quarjo/pollproject/env/lib/python3.12/site-packages/django/db/models/sql/query.py", line 1609, in add_q
    clause, _ = self._add_q(q_object, self.used_aliases)
                ^^^^^^^^^^^^^^^^^^^^^^^^^^^^^^^^^^^^^^^^
  File "/home/quarjo/pollproject/env/lib/python3.12/site-packages/django/db/models/sql/query.py", line 1641, in _add_q
    child_clause, needed_inner = self.build_filter(
                                 ^^^^^^^^^^^^^^^^^^
  File "/home/quarjo/pollproject/env/lib/python3.12/site-packages/django/db/models/sql/query.py", line 1555, in build_filter
    condition = self.build_lookup(lookups, col, value)
                ^^^^^^^^^^^^^^^^^^^^^^^^^^^^^^^^^^^^^^
  File "/home/quarjo/pollproject/env/lib/python3.12/site-packages/django/db/models/sql/query.py", line 1385, in build_lookup
    lookup = lookup_class(lhs, rhs)
             ^^^^^^^^^^^^^^^^^^^^^^
  File "/home/quarjo/pollproject/env/lib/python3.12/site-packages/django/db/models/lookups.py", line 30, in __init__
    self.rhs = self.get_prep_lookup()
               ^^^^^^^^^^^^^^^^^^^^^^
  File "/home/quarjo/pollproject/env/lib/python3.12/site-packages/django/db/models/lookups.py", line 369, in get_prep_lookup
    return super().get_prep_lookup()
           ^^^^^^^^^^^^^^^^^^^^^^^^^
  File "/home/quarjo/pollproject/env/lib/python3.12/site-packages/django/db/models/lookups.py", line 88, in get_prep_lookup
    return self.lhs.output_field.get_prep_value(self.rhs)
           ^^^^^^^^^^^^^^^^^^^^^^^^^^^^^^^^^^^^^^^^^^^^^^
  File "/home/quarjo/pollproject/env/lib/python3.12/site-packages/django/db/models/fields/__init__.py", line 2125, in get_prep_value
    raise e.__class__(
ValueError: Field 'id' expected a number but got 'undefined'.
"GET /payment/poll/undefined/link/ HTTP/1.1" 500 22932
Internal Server Error: /payment/poll/undefined/link/
Traceback (most recent call last):
  File "/home/quarjo/pollproject/env/lib/python3.12/site-packages/django/db/models/fields/__init__.py", line 2123, in get_prep_value
    return int(value)
           ^^^^^^^^^^
ValueError: invalid literal for int() with base 10: 'undefined'

The above exception was the direct cause of the following exception:

Traceback (most recent call last):
  File "/home/quarjo/pollproject/env/lib/python3.12/site-packages/django/core/handlers/exception.py", line 55, in inner
    response = get_response(request)
               ^^^^^^^^^^^^^^^^^^^^^
  File "/home/quarjo/pollproject/env/lib/python3.12/site-packages/django/core/handlers/base.py", line 197, in _get_response
    response = wrapped_callback(request, *callback_args, **callback_kwargs)
               ^^^^^^^^^^^^^^^^^^^^^^^^^^^^^^^^^^^^^^^^^^^^^^^^^^^^^^^^^^^^
  File "/home/quarjo/pollproject/env/lib/python3.12/site-packages/django/views/decorators/csrf.py", line 65, in _view_wrapper
    return view_func(request, *args, **kwargs)
           ^^^^^^^^^^^^^^^^^^^^^^^^^^^^^^^^^^^
  File "/home/quarjo/pollproject/env/lib/python3.12/site-packages/django/views/generic/base.py", line 104, in view
    return self.dispatch(request, *args, **kwargs)
           ^^^^^^^^^^^^^^^^^^^^^^^^^^^^^^^^^^^^^^^
  File "/home/quarjo/pollproject/env/lib/python3.12/site-packages/rest_framework/views.py", line 509, in dispatch
    response = self.handle_exception(exc)
               ^^^^^^^^^^^^^^^^^^^^^^^^^^
  File "/home/quarjo/pollproject/env/lib/python3.12/site-packages/rest_framework/views.py", line 469, in handle_exception
    self.raise_uncaught_exception(exc)
  File "/home/quarjo/pollproject/env/lib/python3.12/site-packages/rest_framework/views.py", line 480, in raise_uncaught_exception
    raise exc
  File "/home/quarjo/pollproject/env/lib/python3.12/site-packages/rest_framework/views.py", line 506, in dispatch
    response = handler(request, *args, **kwargs)
               ^^^^^^^^^^^^^^^^^^^^^^^^^^^^^^^^^
  File "/home/quarjo/pollproject/payment/views.py", line 149, in get
    poll = get_object_or_404(Poll, id=poll_id)
           ^^^^^^^^^^^^^^^^^^^^^^^^^^^^^^^^^^^
  File "/home/quarjo/pollproject/env/lib/python3.12/site-packages/django/shortcuts.py", line 86, in get_object_or_404
    return queryset.get(*args, **kwargs)
           ^^^^^^^^^^^^^^^^^^^^^^^^^^^^^
  File "/home/quarjo/pollproject/env/lib/python3.12/site-packages/django/db/models/query.py", line 635, in get
    clone = self._chain() if self.query.combinator else self.filter(*args, **kwargs)
                                                        ^^^^^^^^^^^^^^^^^^^^^^^^^^^^
  File "/home/quarjo/pollproject/env/lib/python3.12/site-packages/django/db/models/query.py", line 1476, in filter
    return self._filter_or_exclude(False, args, kwargs)
           ^^^^^^^^^^^^^^^^^^^^^^^^^^^^^^^^^^^^^^^^^^^^
  File "/home/quarjo/pollproject/env/lib/python3.12/site-packages/django/db/models/query.py", line 1494, in _filter_or_exclude
    clone._filter_or_exclude_inplace(negate, args, kwargs)
  File "/home/quarjo/pollproject/env/lib/python3.12/site-packages/django/db/models/query.py", line 1501, in _filter_or_exclude_inplace
    self._query.add_q(Q(*args, **kwargs))
  File "/home/quarjo/pollproject/env/lib/python3.12/site-packages/django/db/models/sql/query.py", line 1609, in add_q
    clause, _ = self._add_q(q_object, self.used_aliases)
                ^^^^^^^^^^^^^^^^^^^^^^^^^^^^^^^^^^^^^^^^
  File "/home/quarjo/pollproject/env/lib/python3.12/site-packages/django/db/models/sql/query.py", line 1641, in _add_q
    child_clause, needed_inner = self.build_filter(
                                 ^^^^^^^^^^^^^^^^^^
  File "/home/quarjo/pollproject/env/lib/python3.12/site-packages/django/db/models/sql/query.py", line 1555, in build_filter
    condition = self.build_lookup(lookups, col, value)
                ^^^^^^^^^^^^^^^^^^^^^^^^^^^^^^^^^^^^^^
  File "/home/quarjo/pollproject/env/lib/python3.12/site-packages/django/db/models/sql/query.py", line 1385, in build_lookup
    lookup = lookup_class(lhs, rhs)
             ^^^^^^^^^^^^^^^^^^^^^^
  File "/home/quarjo/pollproject/env/lib/python3.12/site-packages/django/db/models/lookups.py", line 30, in __init__
    self.rhs = self.get_prep_lookup()
               ^^^^^^^^^^^^^^^^^^^^^^
  File "/home/quarjo/pollproject/env/lib/python3.12/site-packages/django/db/models/lookups.py", line 369, in get_prep_lookup
    return super().get_prep_lookup()
           ^^^^^^^^^^^^^^^^^^^^^^^^^
  File "/home/quarjo/pollproject/env/lib/python3.12/site-packages/django/db/models/lookups.py", line 88, in get_prep_lookup
    return self.lhs.output_field.get_prep_value(self.rhs)
           ^^^^^^^^^^^^^^^^^^^^^^^^^^^^^^^^^^^^^^^^^^^^^^
  File "/home/quarjo/pollproject/env/lib/python3.12/site-packages/django/db/models/fields/__init__.py", line 2125, in get_prep_value
    raise e.__class__(
ValueError: Field 'id' expected a number but got 'undefined'.
"GET /payment/poll/undefined/link/ HTTP/1.1" 500 22932
Internal Server Error: /payment/poll/undefined/link/
Traceback (most recent call last):
  File "/home/quarjo/pollproject/env/lib/python3.12/site-packages/django/db/models/fields/__init__.py", line 2123, in get_prep_value
    return int(value)
           ^^^^^^^^^^
ValueError: invalid literal for int() with base 10: 'undefined'

The above exception was the direct cause of the following exception:

Traceback (most recent call last):
  File "/home/quarjo/pollproject/env/lib/python3.12/site-packages/django/core/handlers/exception.py", line 55, in inner
    response = get_response(request)
               ^^^^^^^^^^^^^^^^^^^^^
  File "/home/quarjo/pollproject/env/lib/python3.12/site-packages/django/core/handlers/base.py", line 197, in _get_response
    response = wrapped_callback(request, *callback_args, **callback_kwargs)
               ^^^^^^^^^^^^^^^^^^^^^^^^^^^^^^^^^^^^^^^^^^^^^^^^^^^^^^^^^^^^
  File "/home/quarjo/pollproject/env/lib/python3.12/site-packages/django/views/decorators/csrf.py", line 65, in _view_wrapper
    return view_func(request, *args, **kwargs)
           ^^^^^^^^^^^^^^^^^^^^^^^^^^^^^^^^^^^
  File "/home/quarjo/pollproject/env/lib/python3.12/site-packages/django/views/generic/base.py", line 104, in view
    return self.dispatch(request, *args, **kwargs)
           ^^^^^^^^^^^^^^^^^^^^^^^^^^^^^^^^^^^^^^^
  File "/home/quarjo/pollproject/env/lib/python3.12/site-packages/rest_framework/views.py", line 509, in dispatch
    response = self.handle_exception(exc)
               ^^^^^^^^^^^^^^^^^^^^^^^^^^
  File "/home/quarjo/pollproject/env/lib/python3.12/site-packages/rest_framework/views.py", line 469, in handle_exception
    self.raise_uncaught_exception(exc)
  File "/home/quarjo/pollproject/env/lib/python3.12/site-packages/rest_framework/views.py", line 480, in raise_uncaught_exception
    raise exc
  File "/home/quarjo/pollproject/env/lib/python3.12/site-packages/rest_framework/views.py", line 506, in dispatch
    response = handler(request, *args, **kwargs)
               ^^^^^^^^^^^^^^^^^^^^^^^^^^^^^^^^^
  File "/home/quarjo/pollproject/payment/views.py", line 149, in get
    poll = get_object_or_404(Poll, id=poll_id)
           ^^^^^^^^^^^^^^^^^^^^^^^^^^^^^^^^^^^
  File "/home/quarjo/pollproject/env/lib/python3.12/site-packages/django/shortcuts.py", line 86, in get_object_or_404
    return queryset.get(*args, **kwargs)
           ^^^^^^^^^^^^^^^^^^^^^^^^^^^^^
  File "/home/quarjo/pollproject/env/lib/python3.12/site-packages/django/db/models/query.py", line 635, in get
    clone = self._chain() if self.query.combinator else self.filter(*args, **kwargs)
                                                        ^^^^^^^^^^^^^^^^^^^^^^^^^^^^
  File "/home/quarjo/pollproject/env/lib/python3.12/site-packages/django/db/models/query.py", line 1476, in filter
    return self._filter_or_exclude(False, args, kwargs)
           ^^^^^^^^^^^^^^^^^^^^^^^^^^^^^^^^^^^^^^^^^^^^
  File "/home/quarjo/pollproject/env/lib/python3.12/site-packages/django/db/models/query.py", line 1494, in _filter_or_exclude
    clone._filter_or_exclude_inplace(negate, args, kwargs)
  File "/home/quarjo/pollproject/env/lib/python3.12/site-packages/django/db/models/query.py", line 1501, in _filter_or_exclude_inplace
    self._query.add_q(Q(*args, **kwargs))
  File "/home/quarjo/pollproject/env/lib/python3.12/site-packages/django/db/models/sql/query.py", line 1609, in add_q
    clause, _ = self._add_q(q_object, self.used_aliases)
                ^^^^^^^^^^^^^^^^^^^^^^^^^^^^^^^^^^^^^^^^
  File "/home/quarjo/pollproject/env/lib/python3.12/site-packages/django/db/models/sql/query.py", line 1641, in _add_q
    child_clause, needed_inner = self.build_filter(
                                 ^^^^^^^^^^^^^^^^^^
  File "/home/quarjo/pollproject/env/lib/python3.12/site-packages/django/db/models/sql/query.py", line 1555, in build_filter
    condition = self.build_lookup(lookups, col, value)
                ^^^^^^^^^^^^^^^^^^^^^^^^^^^^^^^^^^^^^^
  File "/home/quarjo/pollproject/env/lib/python3.12/site-packages/django/db/models/sql/query.py", line 1385, in build_lookup
    lookup = lookup_class(lhs, rhs)
             ^^^^^^^^^^^^^^^^^^^^^^
  File "/home/quarjo/pollproject/env/lib/python3.12/site-packages/django/db/models/lookups.py", line 30, in __init__
    self.rhs = self.get_prep_lookup()
               ^^^^^^^^^^^^^^^^^^^^^^
  File "/home/quarjo/pollproject/env/lib/python3.12/site-packages/django/db/models/lookups.py", line 369, in get_prep_lookup
    return super().get_prep_lookup()
           ^^^^^^^^^^^^^^^^^^^^^^^^^
  File "/home/quarjo/pollproject/env/lib/python3.12/site-packages/django/db/models/lookups.py", line 88, in get_prep_lookup
    return self.lhs.output_field.get_prep_value(self.rhs)
           ^^^^^^^^^^^^^^^^^^^^^^^^^^^^^^^^^^^^^^^^^^^^^^
  File "/home/quarjo/pollproject/env/lib/python3.12/site-packages/django/db/models/fields/__init__.py", line 2125, in get_prep_value
    raise e.__class__(
ValueError: Field 'id' expected a number but got 'undefined'.
"GET /payment/poll/undefined/link/ HTTP/1.1" 500 22910
Internal Server Error: /payment/poll/undefined/link/
Traceback (most recent call last):
  File "/home/quarjo/pollproject/env/lib/python3.12/site-packages/django/db/models/fields/__init__.py", line 2123, in get_prep_value
    return int(value)
           ^^^^^^^^^^
ValueError: invalid literal for int() with base 10: 'undefined'

The above exception was the direct cause of the following exception:

Traceback (most recent call last):
  File "/home/quarjo/pollproject/env/lib/python3.12/site-packages/django/core/handlers/exception.py", line 55, in inner
    response = get_response(request)
               ^^^^^^^^^^^^^^^^^^^^^
  File "/home/quarjo/pollproject/env/lib/python3.12/site-packages/django/core/handlers/base.py", line 197, in _get_response
    response = wrapped_callback(request, *callback_args, **callback_kwargs)
               ^^^^^^^^^^^^^^^^^^^^^^^^^^^^^^^^^^^^^^^^^^^^^^^^^^^^^^^^^^^^
  File "/home/quarjo/pollproject/env/lib/python3.12/site-packages/django/views/decorators/csrf.py", line 65, in _view_wrapper
    return view_func(request, *args, **kwargs)
           ^^^^^^^^^^^^^^^^^^^^^^^^^^^^^^^^^^^
  File "/home/quarjo/pollproject/env/lib/python3.12/site-packages/django/views/generic/base.py", line 104, in view
    return self.dispatch(request, *args, **kwargs)
           ^^^^^^^^^^^^^^^^^^^^^^^^^^^^^^^^^^^^^^^
  File "/home/quarjo/pollproject/env/lib/python3.12/site-packages/rest_framework/views.py", line 509, in dispatch
    response = self.handle_exception(exc)
               ^^^^^^^^^^^^^^^^^^^^^^^^^^
  File "/home/quarjo/pollproject/env/lib/python3.12/site-packages/rest_framework/views.py", line 469, in handle_exception
    self.raise_uncaught_exception(exc)
  File "/home/quarjo/pollproject/env/lib/python3.12/site-packages/rest_framework/views.py", line 480, in raise_uncaught_exception
    raise exc
  File "/home/quarjo/pollproject/env/lib/python3.12/site-packages/rest_framework/views.py", line 506, in dispatch
    response = handler(request, *args, **kwargs)
               ^^^^^^^^^^^^^^^^^^^^^^^^^^^^^^^^^
  File "/home/quarjo/pollproject/payment/views.py", line 149, in get
    poll = get_object_or_404(Poll, id=poll_id)
           ^^^^^^^^^^^^^^^^^^^^^^^^^^^^^^^^^^^
  File "/home/quarjo/pollproject/env/lib/python3.12/site-packages/django/shortcuts.py", line 86, in get_object_or_404
    return queryset.get(*args, **kwargs)
           ^^^^^^^^^^^^^^^^^^^^^^^^^^^^^
  File "/home/quarjo/pollproject/env/lib/python3.12/site-packages/django/db/models/query.py", line 635, in get
    clone = self._chain() if self.query.combinator else self.filter(*args, **kwargs)
                                                        ^^^^^^^^^^^^^^^^^^^^^^^^^^^^
  File "/home/quarjo/pollproject/env/lib/python3.12/site-packages/django/db/models/query.py", line 1476, in filter
    return self._filter_or_exclude(False, args, kwargs)
           ^^^^^^^^^^^^^^^^^^^^^^^^^^^^^^^^^^^^^^^^^^^^
  File "/home/quarjo/pollproject/env/lib/python3.12/site-packages/django/db/models/query.py", line 1494, in _filter_or_exclude
    clone._filter_or_exclude_inplace(negate, args, kwargs)
  File "/home/quarjo/pollproject/env/lib/python3.12/site-packages/django/db/models/query.py", line 1501, in _filter_or_exclude_inplace
    self._query.add_q(Q(*args, **kwargs))
  File "/home/quarjo/pollproject/env/lib/python3.12/site-packages/django/db/models/sql/query.py", line 1609, in add_q
    clause, _ = self._add_q(q_object, self.used_aliases)
                ^^^^^^^^^^^^^^^^^^^^^^^^^^^^^^^^^^^^^^^^
  File "/home/quarjo/pollproject/env/lib/python3.12/site-packages/django/db/models/sql/query.py", line 1641, in _add_q
    child_clause, needed_inner = self.build_filter(
                                 ^^^^^^^^^^^^^^^^^^
  File "/home/quarjo/pollproject/env/lib/python3.12/site-packages/django/db/models/sql/query.py", line 1555, in build_filter
    condition = self.build_lookup(lookups, col, value)
                ^^^^^^^^^^^^^^^^^^^^^^^^^^^^^^^^^^^^^^
  File "/home/quarjo/pollproject/env/lib/python3.12/site-packages/django/db/models/sql/query.py", line 1385, in build_lookup
    lookup = lookup_class(lhs, rhs)
             ^^^^^^^^^^^^^^^^^^^^^^
  File "/home/quarjo/pollproject/env/lib/python3.12/site-packages/django/db/models/lookups.py", line 30, in __init__
    self.rhs = self.get_prep_lookup()
               ^^^^^^^^^^^^^^^^^^^^^^
  File "/home/quarjo/pollproject/env/lib/python3.12/site-packages/django/db/models/lookups.py", line 369, in get_prep_lookup
    return super().get_prep_lookup()
           ^^^^^^^^^^^^^^^^^^^^^^^^^
  File "/home/quarjo/pollproject/env/lib/python3.12/site-packages/django/db/models/lookups.py", line 88, in get_prep_lookup
    return self.lhs.output_field.get_prep_value(self.rhs)
           ^^^^^^^^^^^^^^^^^^^^^^^^^^^^^^^^^^^^^^^^^^^^^^
  File "/home/quarjo/pollproject/env/lib/python3.12/site-packages/django/db/models/fields/__init__.py", line 2125, in get_prep_value
    raise e.__class__(
ValueError: Field 'id' expected a number but got 'undefined'.
"GET /payment/poll/undefined/link/ HTTP/1.1" 500 22932
Invalid HTTP_HOST header: '73de-102-176-94-221.ngrok-free.app'. You may need to add '73de-102-176-94-221.ngrok-free.app' to ALLOWED_HOSTS.
Traceback (most recent call last):
  File "/home/quarjo/pollproject/env/lib/python3.12/site-packages/django/core/handlers/exception.py", line 55, in inner
    response = get_response(request)
               ^^^^^^^^^^^^^^^^^^^^^
  File "/home/quarjo/pollproject/env/lib/python3.12/site-packages/django/utils/deprecation.py", line 128, in __call__
    response = self.process_request(request)
               ^^^^^^^^^^^^^^^^^^^^^^^^^^^^^
  File "/home/quarjo/pollproject/env/lib/python3.12/site-packages/django/middleware/common.py", line 48, in process_request
    host = request.get_host()
           ^^^^^^^^^^^^^^^^^^
  File "/home/quarjo/pollproject/env/lib/python3.12/site-packages/django/http/request.py", line 151, in get_host
    raise DisallowedHost(msg)
django.core.exceptions.DisallowedHost: Invalid HTTP_HOST header: '73de-102-176-94-221.ngrok-free.app'. You may need to add '73de-102-176-94-221.ngrok-free.app' to ALLOWED_HOSTS.
Invalid HTTP_HOST header: '73de-102-176-94-221.ngrok-free.app'. You may need to add '73de-102-176-94-221.ngrok-free.app' to ALLOWED_HOSTS.
Traceback (most recent call last):
  File "/home/quarjo/pollproject/env/lib/python3.12/site-packages/django/core/handlers/exception.py", line 55, in inner
    response = get_response(request)
               ^^^^^^^^^^^^^^^^^^^^^
  File "/home/quarjo/pollproject/env/lib/python3.12/site-packages/django/utils/deprecation.py", line 128, in __call__
    response = self.process_request(request)
               ^^^^^^^^^^^^^^^^^^^^^^^^^^^^^
  File "/home/quarjo/pollproject/env/lib/python3.12/site-packages/django/middleware/common.py", line 48, in process_request
    host = request.get_host()
           ^^^^^^^^^^^^^^^^^^
  File "/home/quarjo/pollproject/env/lib/python3.12/site-packages/django/http/request.py", line 151, in get_host
    raise DisallowedHost(msg)
django.core.exceptions.DisallowedHost: Invalid HTTP_HOST header: '73de-102-176-94-221.ngrok-free.app'. You may need to add '73de-102-176-94-221.ngrok-free.app' to ALLOWED_HOSTS.
Invalid HTTP_HOST header: '73de-102-176-94-221.ngrok-free.app'. You may need to add '73de-102-176-94-221.ngrok-free.app' to ALLOWED_HOSTS.
Traceback (most recent call last):
  File "/home/quarjo/pollproject/env/lib/python3.12/site-packages/django/core/handlers/exception.py", line 55, in inner
    response = get_response(request)
               ^^^^^^^^^^^^^^^^^^^^^
  File "/home/quarjo/pollproject/env/lib/python3.12/site-packages/django/utils/deprecation.py", line 128, in __call__
    response = self.process_request(request)
               ^^^^^^^^^^^^^^^^^^^^^^^^^^^^^
  File "/home/quarjo/pollproject/env/lib/python3.12/site-packages/django/middleware/common.py", line 48, in process_request
    host = request.get_host()
           ^^^^^^^^^^^^^^^^^^
  File "/home/quarjo/pollproject/env/lib/python3.12/site-packages/django/http/request.py", line 151, in get_host
    raise DisallowedHost(msg)
django.core.exceptions.DisallowedHost: Invalid HTTP_HOST header: '73de-102-176-94-221.ngrok-free.app'. You may need to add '73de-102-176-94-221.ngrok-free.app' to ALLOWED_HOSTS.
Invalid HTTP_HOST header: '73de-102-176-94-221.ngrok-free.app'. You may need to add '73de-102-176-94-221.ngrok-free.app' to ALLOWED_HOSTS.
Traceback (most recent call last):
  File "/home/quarjo/pollproject/env/lib/python3.12/site-packages/django/core/handlers/exception.py", line 55, in inner
    response = get_response(request)
               ^^^^^^^^^^^^^^^^^^^^^
  File "/home/quarjo/pollproject/env/lib/python3.12/site-packages/django/utils/deprecation.py", line 128, in __call__
    response = self.process_request(request)
               ^^^^^^^^^^^^^^^^^^^^^^^^^^^^^
  File "/home/quarjo/pollproject/env/lib/python3.12/site-packages/django/middleware/common.py", line 48, in process_request
    host = request.get_host()
           ^^^^^^^^^^^^^^^^^^
  File "/home/quarjo/pollproject/env/lib/python3.12/site-packages/django/http/request.py", line 151, in get_host
    raise DisallowedHost(msg)
django.core.exceptions.DisallowedHost: Invalid HTTP_HOST header: '73de-102-176-94-221.ngrok-free.app'. You may need to add '73de-102-176-94-221.ngrok-free.app' to ALLOWED_HOSTS.
Invalid HTTP_HOST header: '73de-102-176-94-221.ngrok-free.app'. You may need to add '73de-102-176-94-221.ngrok-free.app' to ALLOWED_HOSTS.
Traceback (most recent call last):
  File "/home/quarjo/pollproject/env/lib/python3.12/site-packages/django/core/handlers/exception.py", line 55, in inner
    response = get_response(request)
               ^^^^^^^^^^^^^^^^^^^^^
  File "/home/quarjo/pollproject/env/lib/python3.12/site-packages/django/utils/deprecation.py", line 128, in __call__
    response = self.process_request(request)
               ^^^^^^^^^^^^^^^^^^^^^^^^^^^^^
  File "/home/quarjo/pollproject/env/lib/python3.12/site-packages/django/middleware/common.py", line 48, in process_request
    host = request.get_host()
           ^^^^^^^^^^^^^^^^^^
  File "/home/quarjo/pollproject/env/lib/python3.12/site-packages/django/http/request.py", line 151, in get_host
    raise DisallowedHost(msg)
django.core.exceptions.DisallowedHost: Invalid HTTP_HOST header: '73de-102-176-94-221.ngrok-free.app'. You may need to add '73de-102-176-94-221.ngrok-free.app' to ALLOWED_HOSTS.
Invalid HTTP_HOST header: '73de-102-176-94-221.ngrok-free.app'. You may need to add '73de-102-176-94-221.ngrok-free.app' to ALLOWED_HOSTS.
Traceback (most recent call last):
  File "/home/quarjo/pollproject/env/lib/python3.12/site-packages/django/core/handlers/exception.py", line 55, in inner
    response = get_response(request)
               ^^^^^^^^^^^^^^^^^^^^^
  File "/home/quarjo/pollproject/env/lib/python3.12/site-packages/django/utils/deprecation.py", line 128, in __call__
    response = self.process_request(request)
               ^^^^^^^^^^^^^^^^^^^^^^^^^^^^^
  File "/home/quarjo/pollproject/env/lib/python3.12/site-packages/django/middleware/common.py", line 48, in process_request
    host = request.get_host()
           ^^^^^^^^^^^^^^^^^^
  File "/home/quarjo/pollproject/env/lib/python3.12/site-packages/django/http/request.py", line 151, in get_host
    raise DisallowedHost(msg)
django.core.exceptions.DisallowedHost: Invalid HTTP_HOST header: '73de-102-176-94-221.ngrok-free.app'. You may need to add '73de-102-176-94-221.ngrok-free.app' to ALLOWED_HOSTS.
Internal Server Error: /payment/poll/10/link/
"GET /payment/poll/10/link/ HTTP/1.1" 500 61
Internal Server Error: /payment/poll/9/link/
"GET /payment/poll/9/link/ HTTP/1.1" 500 61
Internal Server Error: /payment/poll/8/link/
"GET /payment/poll/8/link/ HTTP/1.1" 500 61
Internal Server Error: /polls/7/contestants/44/update/
Traceback (most recent call last):
  File "/home/quarjo/pollproject/env/lib/python3.12/site-packages/django/core/handlers/exception.py", line 55, in inner
    response = get_response(request)
               ^^^^^^^^^^^^^^^^^^^^^
  File "/home/quarjo/pollproject/env/lib/python3.12/site-packages/django/core/handlers/base.py", line 197, in _get_response
    response = wrapped_callback(request, *callback_args, **callback_kwargs)
               ^^^^^^^^^^^^^^^^^^^^^^^^^^^^^^^^^^^^^^^^^^^^^^^^^^^^^^^^^^^^
  File "/home/quarjo/pollproject/env/lib/python3.12/site-packages/django/views/decorators/csrf.py", line 65, in _view_wrapper
    return view_func(request, *args, **kwargs)
           ^^^^^^^^^^^^^^^^^^^^^^^^^^^^^^^^^^^
  File "/home/quarjo/pollproject/env/lib/python3.12/site-packages/django/views/generic/base.py", line 104, in view
    return self.dispatch(request, *args, **kwargs)
           ^^^^^^^^^^^^^^^^^^^^^^^^^^^^^^^^^^^^^^^
  File "/home/quarjo/pollproject/env/lib/python3.12/site-packages/rest_framework/views.py", line 509, in dispatch
    response = self.handle_exception(exc)
               ^^^^^^^^^^^^^^^^^^^^^^^^^^
  File "/home/quarjo/pollproject/env/lib/python3.12/site-packages/rest_framework/views.py", line 469, in handle_exception
    self.raise_uncaught_exception(exc)
  File "/home/quarjo/pollproject/env/lib/python3.12/site-packages/rest_framework/views.py", line 480, in raise_uncaught_exception
    raise exc
  File "/home/quarjo/pollproject/env/lib/python3.12/site-packages/rest_framework/views.py", line 506, in dispatch
    response = handler(request, *args, **kwargs)
               ^^^^^^^^^^^^^^^^^^^^^^^^^^^^^^^^^
  File "/home/quarjo/pollproject/env/lib/python3.12/site-packages/rest_framework/generics.py", line 230, in put
    return self.update(request, *args, **kwargs)
           ^^^^^^^^^^^^^^^^^^^^^^^^^^^^^^^^^^^^^
  File "/home/quarjo/pollproject/env/lib/python3.12/site-packages/rest_framework/mixins.py", line 65, in update
    instance = self.get_object()
               ^^^^^^^^^^^^^^^^^
  File "/home/quarjo/pollproject/env/lib/python3.12/site-packages/rest_framework/generics.py", line 92, in get_object
    assert lookup_url_kwarg in self.kwargs, (
           ^^^^^^^^^^^^^^^^^^^^^^^^^^^^^^^
AssertionError: Expected view ContestantUpdateView to be called with a URL keyword argument named "pk". Fix your URL conf, or set the `.lookup_field` attribute on the view correctly.
"PUT /polls/7/contestants/44/update/ HTTP/1.1" 500 106685
"PUT /polls/7/contestants/44/update/ HTTP/1.1" 500 59
Internal Server Error: /polls/5/
Traceback (most recent call last):
  File "/home/quarjo/pollproject/env/lib/python3.12/site-packages/django/db/models/sql/query.py", line 2195, in add_fields
    join_info = self.setup_joins(
                ^^^^^^^^^^^^^^^^^
  File "/home/quarjo/pollproject/env/lib/python3.12/site-packages/django/db/models/sql/query.py", line 1863, in setup_joins
    path, final_field, targets, rest = self.names_to_path(
                                       ^^^^^^^^^^^^^^^^^^^
  File "/home/quarjo/pollproject/env/lib/python3.12/site-packages/django/db/models/sql/query.py", line 1768, in names_to_path
    raise FieldError(
django.core.exceptions.FieldError: Cannot resolve keyword 'award' into field. Choices are: category, id, image, name, nominee_code, poll, poll_id, votes

During handling of the above exception, another exception occurred:

Traceback (most recent call last):
  File "/home/quarjo/pollproject/env/lib/python3.12/site-packages/django/core/handlers/exception.py", line 55, in inner
    response = get_response(request)
               ^^^^^^^^^^^^^^^^^^^^^
  File "/home/quarjo/pollproject/env/lib/python3.12/site-packages/django/core/handlers/base.py", line 197, in _get_response
    response = wrapped_callback(request, *callback_args, **callback_kwargs)
               ^^^^^^^^^^^^^^^^^^^^^^^^^^^^^^^^^^^^^^^^^^^^^^^^^^^^^^^^^^^^
  File "/home/quarjo/pollproject/env/lib/python3.12/site-packages/django/views/decorators/csrf.py", line 65, in _view_wrapper
    return view_func(request, *args, **kwargs)
           ^^^^^^^^^^^^^^^^^^^^^^^^^^^^^^^^^^^
  File "/home/quarjo/pollproject/env/lib/python3.12/site-packages/django/views/generic/base.py", line 104, in view
    return self.dispatch(request, *args, **kwargs)
           ^^^^^^^^^^^^^^^^^^^^^^^^^^^^^^^^^^^^^^^
  File "/home/quarjo/pollproject/env/lib/python3.12/site-packages/rest_framework/views.py", line 509, in dispatch
    response = self.handle_exception(exc)
               ^^^^^^^^^^^^^^^^^^^^^^^^^^
  File "/home/quarjo/pollproject/env/lib/python3.12/site-packages/rest_framework/views.py", line 469, in handle_exception
    self.raise_uncaught_exception(exc)
  File "/home/quarjo/pollproject/env/lib/python3.12/site-packages/rest_framework/views.py", line 480, in raise_uncaught_exception
    raise exc
  File "/home/quarjo/pollproject/env/lib/python3.12/site-packages/rest_framework/views.py", line 506, in dispatch
    response = handler(request, *args, **kwargs)
               ^^^^^^^^^^^^^^^^^^^^^^^^^^^^^^^^^
  File "/home/quarjo/pollproject/poll/views.py", line 151, in get
    contestants = poll.contestants.values(
                  ^^^^^^^^^^^^^^^^^^^^^^^^
  File "/home/quarjo/pollproject/env/lib/python3.12/site-packages/django/db/models/manager.py", line 87, in manager_method
    return getattr(self.get_queryset(), name)(*args, **kwargs)
           ^^^^^^^^^^^^^^^^^^^^^^^^^^^^^^^^^^^^^^^^^^^^^^^^^^^
  File "/home/quarjo/pollproject/env/lib/python3.12/site-packages/django/db/models/query.py", line 1360, in values
    clone = self._values(*fields, **expressions)
            ^^^^^^^^^^^^^^^^^^^^^^^^^^^^^^^^^^^^
  File "/home/quarjo/pollproject/env/lib/python3.12/site-packages/django/db/models/query.py", line 1355, in _values
    clone.query.set_values(fields)
  File "/home/quarjo/pollproject/env/lib/python3.12/site-packages/django/db/models/sql/query.py", line 2500, in set_values
    self.add_fields(field_names, True)
  File "/home/quarjo/pollproject/env/lib/python3.12/site-packages/django/db/models/sql/query.py", line 2223, in add_fields
    raise FieldError(
django.core.exceptions.FieldError: Cannot resolve keyword 'award' into field. Choices are: category, id, image, name, nominee_code, poll, poll_id, votes
Internal Server Error: /polls/5/
Traceback (most recent call last):
  File "/home/quarjo/pollproject/env/lib/python3.12/site-packages/django/db/models/sql/query.py", line 2195, in add_fields
    join_info = self.setup_joins(
                ^^^^^^^^^^^^^^^^^
  File "/home/quarjo/pollproject/env/lib/python3.12/site-packages/django/db/models/sql/query.py", line 1863, in setup_joins
    path, final_field, targets, rest = self.names_to_path(
                                       ^^^^^^^^^^^^^^^^^^^
  File "/home/quarjo/pollproject/env/lib/python3.12/site-packages/django/db/models/sql/query.py", line 1768, in names_to_path
    raise FieldError(
django.core.exceptions.FieldError: Cannot resolve keyword 'award' into field. Choices are: category, id, image, name, nominee_code, poll, poll_id, votes

During handling of the above exception, another exception occurred:

Traceback (most recent call last):
  File "/home/quarjo/pollproject/env/lib/python3.12/site-packages/django/core/handlers/exception.py", line 55, in inner
    response = get_response(request)
               ^^^^^^^^^^^^^^^^^^^^^
  File "/home/quarjo/pollproject/env/lib/python3.12/site-packages/django/core/handlers/base.py", line 197, in _get_response
    response = wrapped_callback(request, *callback_args, **callback_kwargs)
               ^^^^^^^^^^^^^^^^^^^^^^^^^^^^^^^^^^^^^^^^^^^^^^^^^^^^^^^^^^^^
  File "/home/quarjo/pollproject/env/lib/python3.12/site-packages/django/views/decorators/csrf.py", line 65, in _view_wrapper
    return view_func(request, *args, **kwargs)
           ^^^^^^^^^^^^^^^^^^^^^^^^^^^^^^^^^^^
  File "/home/quarjo/pollproject/env/lib/python3.12/site-packages/django/views/generic/base.py", line 104, in view
    return self.dispatch(request, *args, **kwargs)
           ^^^^^^^^^^^^^^^^^^^^^^^^^^^^^^^^^^^^^^^
  File "/home/quarjo/pollproject/env/lib/python3.12/site-packages/rest_framework/views.py", line 509, in dispatch
    response = self.handle_exception(exc)
               ^^^^^^^^^^^^^^^^^^^^^^^^^^
  File "/home/quarjo/pollproject/env/lib/python3.12/site-packages/rest_framework/views.py", line 469, in handle_exception
    self.raise_uncaught_exception(exc)
  File "/home/quarjo/pollproject/env/lib/python3.12/site-packages/rest_framework/views.py", line 480, in raise_uncaught_exception
    raise exc
  File "/home/quarjo/pollproject/env/lib/python3.12/site-packages/rest_framework/views.py", line 506, in dispatch
    response = handler(request, *args, **kwargs)
               ^^^^^^^^^^^^^^^^^^^^^^^^^^^^^^^^^
  File "/home/quarjo/pollproject/poll/views.py", line 151, in get
    contestants = poll.contestants.values(
                  ^^^^^^^^^^^^^^^^^^^^^^^^
  File "/home/quarjo/pollproject/env/lib/python3.12/site-packages/django/db/models/manager.py", line 87, in manager_method
    return getattr(self.get_queryset(), name)(*args, **kwargs)
           ^^^^^^^^^^^^^^^^^^^^^^^^^^^^^^^^^^^^^^^^^^^^^^^^^^^
  File "/home/quarjo/pollproject/env/lib/python3.12/site-packages/django/db/models/query.py", line 1360, in values
    clone = self._values(*fields, **expressions)
            ^^^^^^^^^^^^^^^^^^^^^^^^^^^^^^^^^^^^
  File "/home/quarjo/pollproject/env/lib/python3.12/site-packages/django/db/models/query.py", line 1355, in _values
    clone.query.set_values(fields)
  File "/home/quarjo/pollproject/env/lib/python3.12/site-packages/django/db/models/sql/query.py", line 2500, in set_values
    self.add_fields(field_names, True)
  File "/home/quarjo/pollproject/env/lib/python3.12/site-packages/django/db/models/sql/query.py", line 2223, in add_fields
    raise FieldError(
django.core.exceptions.FieldError: Cannot resolve keyword 'award' into field. Choices are: category, id, image, name, nominee_code, poll, poll_id, votes
"GET /polls/5/ HTTP/1.1" 500 21613
"GET /polls/5/ HTTP/1.1" 500 21613
Internal Server Error: /polls/4/
Traceback (most recent call last):
  File "/home/quarjo/pollproject/env/lib/python3.12/site-packages/django/db/models/sql/query.py", line 2195, in add_fields
    join_info = self.setup_joins(
                ^^^^^^^^^^^^^^^^^
  File "/home/quarjo/pollproject/env/lib/python3.12/site-packages/django/db/models/sql/query.py", line 1863, in setup_joins
    path, final_field, targets, rest = self.names_to_path(
                                       ^^^^^^^^^^^^^^^^^^^
  File "/home/quarjo/pollproject/env/lib/python3.12/site-packages/django/db/models/sql/query.py", line 1768, in names_to_path
    raise FieldError(
django.core.exceptions.FieldError: Cannot resolve keyword 'award' into field. Choices are: category, id, image, name, nominee_code, poll, poll_id, votes

During handling of the above exception, another exception occurred:

Traceback (most recent call last):
  File "/home/quarjo/pollproject/env/lib/python3.12/site-packages/django/core/handlers/exception.py", line 55, in inner
    response = get_response(request)
               ^^^^^^^^^^^^^^^^^^^^^
  File "/home/quarjo/pollproject/env/lib/python3.12/site-packages/django/core/handlers/base.py", line 197, in _get_response
    response = wrapped_callback(request, *callback_args, **callback_kwargs)
               ^^^^^^^^^^^^^^^^^^^^^^^^^^^^^^^^^^^^^^^^^^^^^^^^^^^^^^^^^^^^
  File "/home/quarjo/pollproject/env/lib/python3.12/site-packages/django/views/decorators/csrf.py", line 65, in _view_wrapper
    return view_func(request, *args, **kwargs)
           ^^^^^^^^^^^^^^^^^^^^^^^^^^^^^^^^^^^
  File "/home/quarjo/pollproject/env/lib/python3.12/site-packages/django/views/generic/base.py", line 104, in view
    return self.dispatch(request, *args, **kwargs)
           ^^^^^^^^^^^^^^^^^^^^^^^^^^^^^^^^^^^^^^^
  File "/home/quarjo/pollproject/env/lib/python3.12/site-packages/rest_framework/views.py", line 509, in dispatch
    response = self.handle_exception(exc)
               ^^^^^^^^^^^^^^^^^^^^^^^^^^
  File "/home/quarjo/pollproject/env/lib/python3.12/site-packages/rest_framework/views.py", line 469, in handle_exception
    self.raise_uncaught_exception(exc)
  File "/home/quarjo/pollproject/env/lib/python3.12/site-packages/rest_framework/views.py", line 480, in raise_uncaught_exception
    raise exc
  File "/home/quarjo/pollproject/env/lib/python3.12/site-packages/rest_framework/views.py", line 506, in dispatch
    response = handler(request, *args, **kwargs)
               ^^^^^^^^^^^^^^^^^^^^^^^^^^^^^^^^^
  File "/home/quarjo/pollproject/poll/views.py", line 151, in get
    contestants = poll.contestants.values(
                  ^^^^^^^^^^^^^^^^^^^^^^^^
  File "/home/quarjo/pollproject/env/lib/python3.12/site-packages/django/db/models/manager.py", line 87, in manager_method
    return getattr(self.get_queryset(), name)(*args, **kwargs)
           ^^^^^^^^^^^^^^^^^^^^^^^^^^^^^^^^^^^^^^^^^^^^^^^^^^^
  File "/home/quarjo/pollproject/env/lib/python3.12/site-packages/django/db/models/query.py", line 1360, in values
    clone = self._values(*fields, **expressions)
            ^^^^^^^^^^^^^^^^^^^^^^^^^^^^^^^^^^^^
  File "/home/quarjo/pollproject/env/lib/python3.12/site-packages/django/db/models/query.py", line 1355, in _values
    clone.query.set_values(fields)
  File "/home/quarjo/pollproject/env/lib/python3.12/site-packages/django/db/models/sql/query.py", line 2500, in set_values
    self.add_fields(field_names, True)
  File "/home/quarjo/pollproject/env/lib/python3.12/site-packages/django/db/models/sql/query.py", line 2223, in add_fields
    raise FieldError(
django.core.exceptions.FieldError: Cannot resolve keyword 'award' into field. Choices are: category, id, image, name, nominee_code, poll, poll_id, votes
Internal Server Error: /polls/4/
Traceback (most recent call last):
  File "/home/quarjo/pollproject/env/lib/python3.12/site-packages/django/db/models/sql/query.py", line 2195, in add_fields
    join_info = self.setup_joins(
                ^^^^^^^^^^^^^^^^^
  File "/home/quarjo/pollproject/env/lib/python3.12/site-packages/django/db/models/sql/query.py", line 1863, in setup_joins
    path, final_field, targets, rest = self.names_to_path(
                                       ^^^^^^^^^^^^^^^^^^^
  File "/home/quarjo/pollproject/env/lib/python3.12/site-packages/django/db/models/sql/query.py", line 1768, in names_to_path
    raise FieldError(
django.core.exceptions.FieldError: Cannot resolve keyword 'award' into field. Choices are: category, id, image, name, nominee_code, poll, poll_id, votes

During handling of the above exception, another exception occurred:

Traceback (most recent call last):
  File "/home/quarjo/pollproject/env/lib/python3.12/site-packages/django/core/handlers/exception.py", line 55, in inner
    response = get_response(request)
               ^^^^^^^^^^^^^^^^^^^^^
  File "/home/quarjo/pollproject/env/lib/python3.12/site-packages/django/core/handlers/base.py", line 197, in _get_response
    response = wrapped_callback(request, *callback_args, **callback_kwargs)
               ^^^^^^^^^^^^^^^^^^^^^^^^^^^^^^^^^^^^^^^^^^^^^^^^^^^^^^^^^^^^
  File "/home/quarjo/pollproject/env/lib/python3.12/site-packages/django/views/decorators/csrf.py", line 65, in _view_wrapper
    return view_func(request, *args, **kwargs)
           ^^^^^^^^^^^^^^^^^^^^^^^^^^^^^^^^^^^
  File "/home/quarjo/pollproject/env/lib/python3.12/site-packages/django/views/generic/base.py", line 104, in view
    return self.dispatch(request, *args, **kwargs)
           ^^^^^^^^^^^^^^^^^^^^^^^^^^^^^^^^^^^^^^^
  File "/home/quarjo/pollproject/env/lib/python3.12/site-packages/rest_framework/views.py", line 509, in dispatch
    response = self.handle_exception(exc)
               ^^^^^^^^^^^^^^^^^^^^^^^^^^
  File "/home/quarjo/pollproject/env/lib/python3.12/site-packages/rest_framework/views.py", line 469, in handle_exception
    self.raise_uncaught_exception(exc)
  File "/home/quarjo/pollproject/env/lib/python3.12/site-packages/rest_framework/views.py", line 480, in raise_uncaught_exception
    raise exc
  File "/home/quarjo/pollproject/env/lib/python3.12/site-packages/rest_framework/views.py", line 506, in dispatch
    response = handler(request, *args, **kwargs)
               ^^^^^^^^^^^^^^^^^^^^^^^^^^^^^^^^^
  File "/home/quarjo/pollproject/poll/views.py", line 151, in get
    contestants = poll.contestants.values(
                  ^^^^^^^^^^^^^^^^^^^^^^^^
  File "/home/quarjo/pollproject/env/lib/python3.12/site-packages/django/db/models/manager.py", line 87, in manager_method
    return getattr(self.get_queryset(), name)(*args, **kwargs)
           ^^^^^^^^^^^^^^^^^^^^^^^^^^^^^^^^^^^^^^^^^^^^^^^^^^^
  File "/home/quarjo/pollproject/env/lib/python3.12/site-packages/django/db/models/query.py", line 1360, in values
    clone = self._values(*fields, **expressions)
            ^^^^^^^^^^^^^^^^^^^^^^^^^^^^^^^^^^^^
  File "/home/quarjo/pollproject/env/lib/python3.12/site-packages/django/db/models/query.py", line 1355, in _values
    clone.query.set_values(fields)
  File "/home/quarjo/pollproject/env/lib/python3.12/site-packages/django/db/models/sql/query.py", line 2500, in set_values
    self.add_fields(field_names, True)
  File "/home/quarjo/pollproject/env/lib/python3.12/site-packages/django/db/models/sql/query.py", line 2223, in add_fields
    raise FieldError(
django.core.exceptions.FieldError: Cannot resolve keyword 'award' into field. Choices are: category, id, image, name, nominee_code, poll, poll_id, votes
"GET /polls/4/ HTTP/1.1" 500 21613
"GET /polls/4/ HTTP/1.1" 500 21613
Internal Server Error: /polls/5/
Traceback (most recent call last):
  File "/home/quarjo/pollproject/env/lib/python3.12/site-packages/django/db/models/sql/query.py", line 2195, in add_fields
    join_info = self.setup_joins(
                ^^^^^^^^^^^^^^^^^
  File "/home/quarjo/pollproject/env/lib/python3.12/site-packages/django/db/models/sql/query.py", line 1863, in setup_joins
    path, final_field, targets, rest = self.names_to_path(
                                       ^^^^^^^^^^^^^^^^^^^
  File "/home/quarjo/pollproject/env/lib/python3.12/site-packages/django/db/models/sql/query.py", line 1768, in names_to_path
    raise FieldError(
django.core.exceptions.FieldError: Cannot resolve keyword 'award' into field. Choices are: category, id, image, name, nominee_code, poll, poll_id, votes

During handling of the above exception, another exception occurred:

Traceback (most recent call last):
  File "/home/quarjo/pollproject/env/lib/python3.12/site-packages/django/core/handlers/exception.py", line 55, in inner
    response = get_response(request)
               ^^^^^^^^^^^^^^^^^^^^^
  File "/home/quarjo/pollproject/env/lib/python3.12/site-packages/django/core/handlers/base.py", line 197, in _get_response
    response = wrapped_callback(request, *callback_args, **callback_kwargs)
               ^^^^^^^^^^^^^^^^^^^^^^^^^^^^^^^^^^^^^^^^^^^^^^^^^^^^^^^^^^^^
  File "/home/quarjo/pollproject/env/lib/python3.12/site-packages/django/views/decorators/csrf.py", line 65, in _view_wrapper
    return view_func(request, *args, **kwargs)
           ^^^^^^^^^^^^^^^^^^^^^^^^^^^^^^^^^^^
  File "/home/quarjo/pollproject/env/lib/python3.12/site-packages/django/views/generic/base.py", line 104, in view
    return self.dispatch(request, *args, **kwargs)
           ^^^^^^^^^^^^^^^^^^^^^^^^^^^^^^^^^^^^^^^
  File "/home/quarjo/pollproject/env/lib/python3.12/site-packages/rest_framework/views.py", line 509, in dispatch
    response = self.handle_exception(exc)
               ^^^^^^^^^^^^^^^^^^^^^^^^^^
  File "/home/quarjo/pollproject/env/lib/python3.12/site-packages/rest_framework/views.py", line 469, in handle_exception
    self.raise_uncaught_exception(exc)
  File "/home/quarjo/pollproject/env/lib/python3.12/site-packages/rest_framework/views.py", line 480, in raise_uncaught_exception
    raise exc
  File "/home/quarjo/pollproject/env/lib/python3.12/site-packages/rest_framework/views.py", line 506, in dispatch
    response = handler(request, *args, **kwargs)
               ^^^^^^^^^^^^^^^^^^^^^^^^^^^^^^^^^
  File "/home/quarjo/pollproject/poll/views.py", line 151, in get
    contestants = poll.contestants.values(
                  ^^^^^^^^^^^^^^^^^^^^^^^^
  File "/home/quarjo/pollproject/env/lib/python3.12/site-packages/django/db/models/manager.py", line 87, in manager_method
    return getattr(self.get_queryset(), name)(*args, **kwargs)
           ^^^^^^^^^^^^^^^^^^^^^^^^^^^^^^^^^^^^^^^^^^^^^^^^^^^
  File "/home/quarjo/pollproject/env/lib/python3.12/site-packages/django/db/models/query.py", line 1360, in values
    clone = self._values(*fields, **expressions)
            ^^^^^^^^^^^^^^^^^^^^^^^^^^^^^^^^^^^^
  File "/home/quarjo/pollproject/env/lib/python3.12/site-packages/django/db/models/query.py", line 1355, in _values
    clone.query.set_values(fields)
  File "/home/quarjo/pollproject/env/lib/python3.12/site-packages/django/db/models/sql/query.py", line 2500, in set_values
    self.add_fields(field_names, True)
  File "/home/quarjo/pollproject/env/lib/python3.12/site-packages/django/db/models/sql/query.py", line 2223, in add_fields
    raise FieldError(
django.core.exceptions.FieldError: Cannot resolve keyword 'award' into field. Choices are: category, id, image, name, nominee_code, poll, poll_id, votes
"GET /polls/5/ HTTP/1.1" 500 21613
Internal Server Error: /polls/5/
Traceback (most recent call last):
  File "/home/quarjo/pollproject/env/lib/python3.12/site-packages/django/db/models/sql/query.py", line 2195, in add_fields
    join_info = self.setup_joins(
                ^^^^^^^^^^^^^^^^^
  File "/home/quarjo/pollproject/env/lib/python3.12/site-packages/django/db/models/sql/query.py", line 1863, in setup_joins
    path, final_field, targets, rest = self.names_to_path(
                                       ^^^^^^^^^^^^^^^^^^^
  File "/home/quarjo/pollproject/env/lib/python3.12/site-packages/django/db/models/sql/query.py", line 1768, in names_to_path
    raise FieldError(
django.core.exceptions.FieldError: Cannot resolve keyword 'award' into field. Choices are: category, id, image, name, nominee_code, poll, poll_id, votes

During handling of the above exception, another exception occurred:

Traceback (most recent call last):
  File "/home/quarjo/pollproject/env/lib/python3.12/site-packages/django/core/handlers/exception.py", line 55, in inner
    response = get_response(request)
               ^^^^^^^^^^^^^^^^^^^^^
  File "/home/quarjo/pollproject/env/lib/python3.12/site-packages/django/core/handlers/base.py", line 197, in _get_response
    response = wrapped_callback(request, *callback_args, **callback_kwargs)
               ^^^^^^^^^^^^^^^^^^^^^^^^^^^^^^^^^^^^^^^^^^^^^^^^^^^^^^^^^^^^
  File "/home/quarjo/pollproject/env/lib/python3.12/site-packages/django/views/decorators/csrf.py", line 65, in _view_wrapper
    return view_func(request, *args, **kwargs)
           ^^^^^^^^^^^^^^^^^^^^^^^^^^^^^^^^^^^
  File "/home/quarjo/pollproject/env/lib/python3.12/site-packages/django/views/generic/base.py", line 104, in view
    return self.dispatch(request, *args, **kwargs)
           ^^^^^^^^^^^^^^^^^^^^^^^^^^^^^^^^^^^^^^^
  File "/home/quarjo/pollproject/env/lib/python3.12/site-packages/rest_framework/views.py", line 509, in dispatch
    response = self.handle_exception(exc)
               ^^^^^^^^^^^^^^^^^^^^^^^^^^
  File "/home/quarjo/pollproject/env/lib/python3.12/site-packages/rest_framework/views.py", line 469, in handle_exception
    self.raise_uncaught_exception(exc)
  File "/home/quarjo/pollproject/env/lib/python3.12/site-packages/rest_framework/views.py", line 480, in raise_uncaught_exception
    raise exc
  File "/home/quarjo/pollproject/env/lib/python3.12/site-packages/rest_framework/views.py", line 506, in dispatch
    response = handler(request, *args, **kwargs)
               ^^^^^^^^^^^^^^^^^^^^^^^^^^^^^^^^^
  File "/home/quarjo/pollproject/poll/views.py", line 151, in get
    contestants = poll.contestants.values(
                  ^^^^^^^^^^^^^^^^^^^^^^^^
  File "/home/quarjo/pollproject/env/lib/python3.12/site-packages/django/db/models/manager.py", line 87, in manager_method
    return getattr(self.get_queryset(), name)(*args, **kwargs)
           ^^^^^^^^^^^^^^^^^^^^^^^^^^^^^^^^^^^^^^^^^^^^^^^^^^^
  File "/home/quarjo/pollproject/env/lib/python3.12/site-packages/django/db/models/query.py", line 1360, in values
    clone = self._values(*fields, **expressions)
            ^^^^^^^^^^^^^^^^^^^^^^^^^^^^^^^^^^^^
  File "/home/quarjo/pollproject/env/lib/python3.12/site-packages/django/db/models/query.py", line 1355, in _values
    clone.query.set_values(fields)
  File "/home/quarjo/pollproject/env/lib/python3.12/site-packages/django/db/models/sql/query.py", line 2500, in set_values
    self.add_fields(field_names, True)
  File "/home/quarjo/pollproject/env/lib/python3.12/site-packages/django/db/models/sql/query.py", line 2223, in add_fields
    raise FieldError(
django.core.exceptions.FieldError: Cannot resolve keyword 'award' into field. Choices are: category, id, image, name, nominee_code, poll, poll_id, votes
"GET /polls/5/ HTTP/1.1" 500 21613
Internal Server Error: /polls/4/
Traceback (most recent call last):
  File "/home/quarjo/pollproject/env/lib/python3.12/site-packages/django/db/models/sql/query.py", line 2195, in add_fields
    join_info = self.setup_joins(
                ^^^^^^^^^^^^^^^^^
  File "/home/quarjo/pollproject/env/lib/python3.12/site-packages/django/db/models/sql/query.py", line 1863, in setup_joins
    path, final_field, targets, rest = self.names_to_path(
                                       ^^^^^^^^^^^^^^^^^^^
  File "/home/quarjo/pollproject/env/lib/python3.12/site-packages/django/db/models/sql/query.py", line 1768, in names_to_path
    raise FieldError(
django.core.exceptions.FieldError: Cannot resolve keyword 'award' into field. Choices are: category, id, image, name, nominee_code, poll, poll_id, votes

During handling of the above exception, another exception occurred:

Traceback (most recent call last):
  File "/home/quarjo/pollproject/env/lib/python3.12/site-packages/django/core/handlers/exception.py", line 55, in inner
    response = get_response(request)
               ^^^^^^^^^^^^^^^^^^^^^
  File "/home/quarjo/pollproject/env/lib/python3.12/site-packages/django/core/handlers/base.py", line 197, in _get_response
    response = wrapped_callback(request, *callback_args, **callback_kwargs)
               ^^^^^^^^^^^^^^^^^^^^^^^^^^^^^^^^^^^^^^^^^^^^^^^^^^^^^^^^^^^^
  File "/home/quarjo/pollproject/env/lib/python3.12/site-packages/django/views/decorators/csrf.py", line 65, in _view_wrapper
    return view_func(request, *args, **kwargs)
           ^^^^^^^^^^^^^^^^^^^^^^^^^^^^^^^^^^^
  File "/home/quarjo/pollproject/env/lib/python3.12/site-packages/django/views/generic/base.py", line 104, in view
    return self.dispatch(request, *args, **kwargs)
           ^^^^^^^^^^^^^^^^^^^^^^^^^^^^^^^^^^^^^^^
  File "/home/quarjo/pollproject/env/lib/python3.12/site-packages/rest_framework/views.py", line 509, in dispatch
    response = self.handle_exception(exc)
               ^^^^^^^^^^^^^^^^^^^^^^^^^^
  File "/home/quarjo/pollproject/env/lib/python3.12/site-packages/rest_framework/views.py", line 469, in handle_exception
    self.raise_uncaught_exception(exc)
  File "/home/quarjo/pollproject/env/lib/python3.12/site-packages/rest_framework/views.py", line 480, in raise_uncaught_exception
    raise exc
  File "/home/quarjo/pollproject/env/lib/python3.12/site-packages/rest_framework/views.py", line 506, in dispatch
    response = handler(request, *args, **kwargs)
               ^^^^^^^^^^^^^^^^^^^^^^^^^^^^^^^^^
  File "/home/quarjo/pollproject/poll/views.py", line 151, in get
    contestants = poll.contestants.values(
                  ^^^^^^^^^^^^^^^^^^^^^^^^
  File "/home/quarjo/pollproject/env/lib/python3.12/site-packages/django/db/models/manager.py", line 87, in manager_method
    return getattr(self.get_queryset(), name)(*args, **kwargs)
           ^^^^^^^^^^^^^^^^^^^^^^^^^^^^^^^^^^^^^^^^^^^^^^^^^^^
  File "/home/quarjo/pollproject/env/lib/python3.12/site-packages/django/db/models/query.py", line 1360, in values
    clone = self._values(*fields, **expressions)
            ^^^^^^^^^^^^^^^^^^^^^^^^^^^^^^^^^^^^
  File "/home/quarjo/pollproject/env/lib/python3.12/site-packages/django/db/models/query.py", line 1355, in _values
    clone.query.set_values(fields)
  File "/home/quarjo/pollproject/env/lib/python3.12/site-packages/django/db/models/sql/query.py", line 2500, in set_values
    self.add_fields(field_names, True)
  File "/home/quarjo/pollproject/env/lib/python3.12/site-packages/django/db/models/sql/query.py", line 2223, in add_fields
    raise FieldError(
django.core.exceptions.FieldError: Cannot resolve keyword 'award' into field. Choices are: category, id, image, name, nominee_code, poll, poll_id, votes
"GET /polls/4/ HTTP/1.1" 500 21613
Internal Server Error: /polls/4/
Traceback (most recent call last):
  File "/home/quarjo/pollproject/env/lib/python3.12/site-packages/django/db/models/sql/query.py", line 2195, in add_fields
    join_info = self.setup_joins(
                ^^^^^^^^^^^^^^^^^
  File "/home/quarjo/pollproject/env/lib/python3.12/site-packages/django/db/models/sql/query.py", line 1863, in setup_joins
    path, final_field, targets, rest = self.names_to_path(
                                       ^^^^^^^^^^^^^^^^^^^
  File "/home/quarjo/pollproject/env/lib/python3.12/site-packages/django/db/models/sql/query.py", line 1768, in names_to_path
    raise FieldError(
django.core.exceptions.FieldError: Cannot resolve keyword 'award' into field. Choices are: category, id, image, name, nominee_code, poll, poll_id, votes

During handling of the above exception, another exception occurred:

Traceback (most recent call last):
  File "/home/quarjo/pollproject/env/lib/python3.12/site-packages/django/core/handlers/exception.py", line 55, in inner
    response = get_response(request)
               ^^^^^^^^^^^^^^^^^^^^^
  File "/home/quarjo/pollproject/env/lib/python3.12/site-packages/django/core/handlers/base.py", line 197, in _get_response
    response = wrapped_callback(request, *callback_args, **callback_kwargs)
               ^^^^^^^^^^^^^^^^^^^^^^^^^^^^^^^^^^^^^^^^^^^^^^^^^^^^^^^^^^^^
  File "/home/quarjo/pollproject/env/lib/python3.12/site-packages/django/views/decorators/csrf.py", line 65, in _view_wrapper
    return view_func(request, *args, **kwargs)
           ^^^^^^^^^^^^^^^^^^^^^^^^^^^^^^^^^^^
  File "/home/quarjo/pollproject/env/lib/python3.12/site-packages/django/views/generic/base.py", line 104, in view
    return self.dispatch(request, *args, **kwargs)
           ^^^^^^^^^^^^^^^^^^^^^^^^^^^^^^^^^^^^^^^
  File "/home/quarjo/pollproject/env/lib/python3.12/site-packages/rest_framework/views.py", line 509, in dispatch
    response = self.handle_exception(exc)
               ^^^^^^^^^^^^^^^^^^^^^^^^^^
  File "/home/quarjo/pollproject/env/lib/python3.12/site-packages/rest_framework/views.py", line 469, in handle_exception
    self.raise_uncaught_exception(exc)
  File "/home/quarjo/pollproject/env/lib/python3.12/site-packages/rest_framework/views.py", line 480, in raise_uncaught_exception
    raise exc
  File "/home/quarjo/pollproject/env/lib/python3.12/site-packages/rest_framework/views.py", line 506, in dispatch
    response = handler(request, *args, **kwargs)
               ^^^^^^^^^^^^^^^^^^^^^^^^^^^^^^^^^
  File "/home/quarjo/pollproject/poll/views.py", line 151, in get
    contestants = poll.contestants.values(
                  ^^^^^^^^^^^^^^^^^^^^^^^^
  File "/home/quarjo/pollproject/env/lib/python3.12/site-packages/django/db/models/manager.py", line 87, in manager_method
    return getattr(self.get_queryset(), name)(*args, **kwargs)
           ^^^^^^^^^^^^^^^^^^^^^^^^^^^^^^^^^^^^^^^^^^^^^^^^^^^
  File "/home/quarjo/pollproject/env/lib/python3.12/site-packages/django/db/models/query.py", line 1360, in values
    clone = self._values(*fields, **expressions)
            ^^^^^^^^^^^^^^^^^^^^^^^^^^^^^^^^^^^^
  File "/home/quarjo/pollproject/env/lib/python3.12/site-packages/django/db/models/query.py", line 1355, in _values
    clone.query.set_values(fields)
  File "/home/quarjo/pollproject/env/lib/python3.12/site-packages/django/db/models/sql/query.py", line 2500, in set_values
    self.add_fields(field_names, True)
  File "/home/quarjo/pollproject/env/lib/python3.12/site-packages/django/db/models/sql/query.py", line 2223, in add_fields
    raise FieldError(
django.core.exceptions.FieldError: Cannot resolve keyword 'award' into field. Choices are: category, id, image, name, nominee_code, poll, poll_id, votes
"GET /polls/4/ HTTP/1.1" 500 21613
Internal Server Error: /polls/6/
Traceback (most recent call last):
  File "/home/quarjo/pollproject/env/lib/python3.12/site-packages/django/db/models/sql/query.py", line 2195, in add_fields
    join_info = self.setup_joins(
                ^^^^^^^^^^^^^^^^^
  File "/home/quarjo/pollproject/env/lib/python3.12/site-packages/django/db/models/sql/query.py", line 1863, in setup_joins
    path, final_field, targets, rest = self.names_to_path(
                                       ^^^^^^^^^^^^^^^^^^^
  File "/home/quarjo/pollproject/env/lib/python3.12/site-packages/django/db/models/sql/query.py", line 1768, in names_to_path
    raise FieldError(
django.core.exceptions.FieldError: Cannot resolve keyword 'award' into field. Choices are: category, id, image, name, nominee_code, poll, poll_id, votes

During handling of the above exception, another exception occurred:

Traceback (most recent call last):
  File "/home/quarjo/pollproject/env/lib/python3.12/site-packages/django/core/handlers/exception.py", line 55, in inner
    response = get_response(request)
               ^^^^^^^^^^^^^^^^^^^^^
  File "/home/quarjo/pollproject/env/lib/python3.12/site-packages/django/core/handlers/base.py", line 197, in _get_response
    response = wrapped_callback(request, *callback_args, **callback_kwargs)
               ^^^^^^^^^^^^^^^^^^^^^^^^^^^^^^^^^^^^^^^^^^^^^^^^^^^^^^^^^^^^
  File "/home/quarjo/pollproject/env/lib/python3.12/site-packages/django/views/decorators/csrf.py", line 65, in _view_wrapper
    return view_func(request, *args, **kwargs)
           ^^^^^^^^^^^^^^^^^^^^^^^^^^^^^^^^^^^
  File "/home/quarjo/pollproject/env/lib/python3.12/site-packages/django/views/generic/base.py", line 104, in view
    return self.dispatch(request, *args, **kwargs)
           ^^^^^^^^^^^^^^^^^^^^^^^^^^^^^^^^^^^^^^^
  File "/home/quarjo/pollproject/env/lib/python3.12/site-packages/rest_framework/views.py", line 509, in dispatch
    response = self.handle_exception(exc)
               ^^^^^^^^^^^^^^^^^^^^^^^^^^
  File "/home/quarjo/pollproject/env/lib/python3.12/site-packages/rest_framework/views.py", line 469, in handle_exception
    self.raise_uncaught_exception(exc)
  File "/home/quarjo/pollproject/env/lib/python3.12/site-packages/rest_framework/views.py", line 480, in raise_uncaught_exception
    raise exc
  File "/home/quarjo/pollproject/env/lib/python3.12/site-packages/rest_framework/views.py", line 506, in dispatch
    response = handler(request, *args, **kwargs)
               ^^^^^^^^^^^^^^^^^^^^^^^^^^^^^^^^^
  File "/home/quarjo/pollproject/poll/views.py", line 151, in get
    contestants = poll.contestants.values(
                  ^^^^^^^^^^^^^^^^^^^^^^^^
  File "/home/quarjo/pollproject/env/lib/python3.12/site-packages/django/db/models/manager.py", line 87, in manager_method
    return getattr(self.get_queryset(), name)(*args, **kwargs)
           ^^^^^^^^^^^^^^^^^^^^^^^^^^^^^^^^^^^^^^^^^^^^^^^^^^^
  File "/home/quarjo/pollproject/env/lib/python3.12/site-packages/django/db/models/query.py", line 1360, in values
    clone = self._values(*fields, **expressions)
            ^^^^^^^^^^^^^^^^^^^^^^^^^^^^^^^^^^^^
  File "/home/quarjo/pollproject/env/lib/python3.12/site-packages/django/db/models/query.py", line 1355, in _values
    clone.query.set_values(fields)
  File "/home/quarjo/pollproject/env/lib/python3.12/site-packages/django/db/models/sql/query.py", line 2500, in set_values
    self.add_fields(field_names, True)
  File "/home/quarjo/pollproject/env/lib/python3.12/site-packages/django/db/models/sql/query.py", line 2223, in add_fields
    raise FieldError(
django.core.exceptions.FieldError: Cannot resolve keyword 'award' into field. Choices are: category, id, image, name, nominee_code, poll, poll_id, votes
"GET /polls/6/ HTTP/1.1" 500 21613
Internal Server Error: /polls/6/
Traceback (most recent call last):
  File "/home/quarjo/pollproject/env/lib/python3.12/site-packages/django/db/models/sql/query.py", line 2195, in add_fields
    join_info = self.setup_joins(
                ^^^^^^^^^^^^^^^^^
  File "/home/quarjo/pollproject/env/lib/python3.12/site-packages/django/db/models/sql/query.py", line 1863, in setup_joins
    path, final_field, targets, rest = self.names_to_path(
                                       ^^^^^^^^^^^^^^^^^^^
  File "/home/quarjo/pollproject/env/lib/python3.12/site-packages/django/db/models/sql/query.py", line 1768, in names_to_path
    raise FieldError(
django.core.exceptions.FieldError: Cannot resolve keyword 'award' into field. Choices are: category, id, image, name, nominee_code, poll, poll_id, votes

During handling of the above exception, another exception occurred:

Traceback (most recent call last):
  File "/home/quarjo/pollproject/env/lib/python3.12/site-packages/django/core/handlers/exception.py", line 55, in inner
    response = get_response(request)
               ^^^^^^^^^^^^^^^^^^^^^
  File "/home/quarjo/pollproject/env/lib/python3.12/site-packages/django/core/handlers/base.py", line 197, in _get_response
    response = wrapped_callback(request, *callback_args, **callback_kwargs)
               ^^^^^^^^^^^^^^^^^^^^^^^^^^^^^^^^^^^^^^^^^^^^^^^^^^^^^^^^^^^^
  File "/home/quarjo/pollproject/env/lib/python3.12/site-packages/django/views/decorators/csrf.py", line 65, in _view_wrapper
    return view_func(request, *args, **kwargs)
           ^^^^^^^^^^^^^^^^^^^^^^^^^^^^^^^^^^^
  File "/home/quarjo/pollproject/env/lib/python3.12/site-packages/django/views/generic/base.py", line 104, in view
    return self.dispatch(request, *args, **kwargs)
           ^^^^^^^^^^^^^^^^^^^^^^^^^^^^^^^^^^^^^^^
  File "/home/quarjo/pollproject/env/lib/python3.12/site-packages/rest_framework/views.py", line 509, in dispatch
    response = self.handle_exception(exc)
               ^^^^^^^^^^^^^^^^^^^^^^^^^^
  File "/home/quarjo/pollproject/env/lib/python3.12/site-packages/rest_framework/views.py", line 469, in handle_exception
    self.raise_uncaught_exception(exc)
  File "/home/quarjo/pollproject/env/lib/python3.12/site-packages/rest_framework/views.py", line 480, in raise_uncaught_exception
    raise exc
  File "/home/quarjo/pollproject/env/lib/python3.12/site-packages/rest_framework/views.py", line 506, in dispatch
    response = handler(request, *args, **kwargs)
               ^^^^^^^^^^^^^^^^^^^^^^^^^^^^^^^^^
  File "/home/quarjo/pollproject/poll/views.py", line 151, in get
    contestants = poll.contestants.values(
                  ^^^^^^^^^^^^^^^^^^^^^^^^
  File "/home/quarjo/pollproject/env/lib/python3.12/site-packages/django/db/models/manager.py", line 87, in manager_method
    return getattr(self.get_queryset(), name)(*args, **kwargs)
           ^^^^^^^^^^^^^^^^^^^^^^^^^^^^^^^^^^^^^^^^^^^^^^^^^^^
  File "/home/quarjo/pollproject/env/lib/python3.12/site-packages/django/db/models/query.py", line 1360, in values
    clone = self._values(*fields, **expressions)
            ^^^^^^^^^^^^^^^^^^^^^^^^^^^^^^^^^^^^
  File "/home/quarjo/pollproject/env/lib/python3.12/site-packages/django/db/models/query.py", line 1355, in _values
    clone.query.set_values(fields)
  File "/home/quarjo/pollproject/env/lib/python3.12/site-packages/django/db/models/sql/query.py", line 2500, in set_values
    self.add_fields(field_names, True)
  File "/home/quarjo/pollproject/env/lib/python3.12/site-packages/django/db/models/sql/query.py", line 2223, in add_fields
    raise FieldError(
django.core.exceptions.FieldError: Cannot resolve keyword 'award' into field. Choices are: category, id, image, name, nominee_code, poll, poll_id, votes
"GET /polls/6/ HTTP/1.1" 500 21613
Internal Server Error: /polls/6/
Traceback (most recent call last):
  File "/home/quarjo/pollproject/env/lib/python3.12/site-packages/django/db/models/sql/query.py", line 2195, in add_fields
    join_info = self.setup_joins(
                ^^^^^^^^^^^^^^^^^
  File "/home/quarjo/pollproject/env/lib/python3.12/site-packages/django/db/models/sql/query.py", line 1863, in setup_joins
    path, final_field, targets, rest = self.names_to_path(
                                       ^^^^^^^^^^^^^^^^^^^
  File "/home/quarjo/pollproject/env/lib/python3.12/site-packages/django/db/models/sql/query.py", line 1768, in names_to_path
    raise FieldError(
django.core.exceptions.FieldError: Cannot resolve keyword 'award' into field. Choices are: category, id, image, name, nominee_code, poll, poll_id, votes

During handling of the above exception, another exception occurred:

Traceback (most recent call last):
  File "/home/quarjo/pollproject/env/lib/python3.12/site-packages/django/core/handlers/exception.py", line 55, in inner
    response = get_response(request)
               ^^^^^^^^^^^^^^^^^^^^^
  File "/home/quarjo/pollproject/env/lib/python3.12/site-packages/django/core/handlers/base.py", line 197, in _get_response
    response = wrapped_callback(request, *callback_args, **callback_kwargs)
               ^^^^^^^^^^^^^^^^^^^^^^^^^^^^^^^^^^^^^^^^^^^^^^^^^^^^^^^^^^^^
  File "/home/quarjo/pollproject/env/lib/python3.12/site-packages/django/views/decorators/csrf.py", line 65, in _view_wrapper
    return view_func(request, *args, **kwargs)
           ^^^^^^^^^^^^^^^^^^^^^^^^^^^^^^^^^^^
  File "/home/quarjo/pollproject/env/lib/python3.12/site-packages/django/views/generic/base.py", line 104, in view
    return self.dispatch(request, *args, **kwargs)
           ^^^^^^^^^^^^^^^^^^^^^^^^^^^^^^^^^^^^^^^
  File "/home/quarjo/pollproject/env/lib/python3.12/site-packages/rest_framework/views.py", line 509, in dispatch
    response = self.handle_exception(exc)
               ^^^^^^^^^^^^^^^^^^^^^^^^^^
  File "/home/quarjo/pollproject/env/lib/python3.12/site-packages/rest_framework/views.py", line 469, in handle_exception
    self.raise_uncaught_exception(exc)
  File "/home/quarjo/pollproject/env/lib/python3.12/site-packages/rest_framework/views.py", line 480, in raise_uncaught_exception
    raise exc
  File "/home/quarjo/pollproject/env/lib/python3.12/site-packages/rest_framework/views.py", line 506, in dispatch
    response = handler(request, *args, **kwargs)
               ^^^^^^^^^^^^^^^^^^^^^^^^^^^^^^^^^
  File "/home/quarjo/pollproject/poll/views.py", line 151, in get
    contestants = poll.contestants.values(
                  ^^^^^^^^^^^^^^^^^^^^^^^^
  File "/home/quarjo/pollproject/env/lib/python3.12/site-packages/django/db/models/manager.py", line 87, in manager_method
    return getattr(self.get_queryset(), name)(*args, **kwargs)
           ^^^^^^^^^^^^^^^^^^^^^^^^^^^^^^^^^^^^^^^^^^^^^^^^^^^
  File "/home/quarjo/pollproject/env/lib/python3.12/site-packages/django/db/models/query.py", line 1360, in values
    clone = self._values(*fields, **expressions)
            ^^^^^^^^^^^^^^^^^^^^^^^^^^^^^^^^^^^^
  File "/home/quarjo/pollproject/env/lib/python3.12/site-packages/django/db/models/query.py", line 1355, in _values
    clone.query.set_values(fields)
  File "/home/quarjo/pollproject/env/lib/python3.12/site-packages/django/db/models/sql/query.py", line 2500, in set_values
    self.add_fields(field_names, True)
  File "/home/quarjo/pollproject/env/lib/python3.12/site-packages/django/db/models/sql/query.py", line 2223, in add_fields
    raise FieldError(
django.core.exceptions.FieldError: Cannot resolve keyword 'award' into field. Choices are: category, id, image, name, nominee_code, poll, poll_id, votes
"GET /polls/6/ HTTP/1.1" 500 21613
Internal Server Error: /polls/6/
Traceback (most recent call last):
  File "/home/quarjo/pollproject/env/lib/python3.12/site-packages/django/db/models/sql/query.py", line 2195, in add_fields
    join_info = self.setup_joins(
                ^^^^^^^^^^^^^^^^^
  File "/home/quarjo/pollproject/env/lib/python3.12/site-packages/django/db/models/sql/query.py", line 1863, in setup_joins
    path, final_field, targets, rest = self.names_to_path(
                                       ^^^^^^^^^^^^^^^^^^^
  File "/home/quarjo/pollproject/env/lib/python3.12/site-packages/django/db/models/sql/query.py", line 1768, in names_to_path
    raise FieldError(
django.core.exceptions.FieldError: Cannot resolve keyword 'award' into field. Choices are: category, id, image, name, nominee_code, poll, poll_id, votes

During handling of the above exception, another exception occurred:

Traceback (most recent call last):
  File "/home/quarjo/pollproject/env/lib/python3.12/site-packages/django/core/handlers/exception.py", line 55, in inner
    response = get_response(request)
               ^^^^^^^^^^^^^^^^^^^^^
  File "/home/quarjo/pollproject/env/lib/python3.12/site-packages/django/core/handlers/base.py", line 197, in _get_response
    response = wrapped_callback(request, *callback_args, **callback_kwargs)
               ^^^^^^^^^^^^^^^^^^^^^^^^^^^^^^^^^^^^^^^^^^^^^^^^^^^^^^^^^^^^
  File "/home/quarjo/pollproject/env/lib/python3.12/site-packages/django/views/decorators/csrf.py", line 65, in _view_wrapper
    return view_func(request, *args, **kwargs)
           ^^^^^^^^^^^^^^^^^^^^^^^^^^^^^^^^^^^
  File "/home/quarjo/pollproject/env/lib/python3.12/site-packages/django/views/generic/base.py", line 104, in view
    return self.dispatch(request, *args, **kwargs)
           ^^^^^^^^^^^^^^^^^^^^^^^^^^^^^^^^^^^^^^^
  File "/home/quarjo/pollproject/env/lib/python3.12/site-packages/rest_framework/views.py", line 509, in dispatch
    response = self.handle_exception(exc)
               ^^^^^^^^^^^^^^^^^^^^^^^^^^
  File "/home/quarjo/pollproject/env/lib/python3.12/site-packages/rest_framework/views.py", line 469, in handle_exception
    self.raise_uncaught_exception(exc)
  File "/home/quarjo/pollproject/env/lib/python3.12/site-packages/rest_framework/views.py", line 480, in raise_uncaught_exception
    raise exc
  File "/home/quarjo/pollproject/env/lib/python3.12/site-packages/rest_framework/views.py", line 506, in dispatch
    response = handler(request, *args, **kwargs)
               ^^^^^^^^^^^^^^^^^^^^^^^^^^^^^^^^^
  File "/home/quarjo/pollproject/poll/views.py", line 151, in get
    contestants = poll.contestants.values(
                  ^^^^^^^^^^^^^^^^^^^^^^^^
  File "/home/quarjo/pollproject/env/lib/python3.12/site-packages/django/db/models/manager.py", line 87, in manager_method
    return getattr(self.get_queryset(), name)(*args, **kwargs)
           ^^^^^^^^^^^^^^^^^^^^^^^^^^^^^^^^^^^^^^^^^^^^^^^^^^^
  File "/home/quarjo/pollproject/env/lib/python3.12/site-packages/django/db/models/query.py", line 1360, in values
    clone = self._values(*fields, **expressions)
            ^^^^^^^^^^^^^^^^^^^^^^^^^^^^^^^^^^^^
  File "/home/quarjo/pollproject/env/lib/python3.12/site-packages/django/db/models/query.py", line 1355, in _values
    clone.query.set_values(fields)
  File "/home/quarjo/pollproject/env/lib/python3.12/site-packages/django/db/models/sql/query.py", line 2500, in set_values
    self.add_fields(field_names, True)
  File "/home/quarjo/pollproject/env/lib/python3.12/site-packages/django/db/models/sql/query.py", line 2223, in add_fields
    raise FieldError(
django.core.exceptions.FieldError: Cannot resolve keyword 'award' into field. Choices are: category, id, image, name, nominee_code, poll, poll_id, votes
"GET /polls/6/ HTTP/1.1" 500 21613
Internal Server Error: /polls/6/
Traceback (most recent call last):
  File "/home/quarjo/pollproject/env/lib/python3.12/site-packages/django/db/models/sql/query.py", line 2195, in add_fields
    join_info = self.setup_joins(
                ^^^^^^^^^^^^^^^^^
  File "/home/quarjo/pollproject/env/lib/python3.12/site-packages/django/db/models/sql/query.py", line 1863, in setup_joins
    path, final_field, targets, rest = self.names_to_path(
                                       ^^^^^^^^^^^^^^^^^^^
  File "/home/quarjo/pollproject/env/lib/python3.12/site-packages/django/db/models/sql/query.py", line 1768, in names_to_path
    raise FieldError(
django.core.exceptions.FieldError: Cannot resolve keyword 'award' into field. Choices are: category, id, image, name, nominee_code, poll, poll_id, votes

During handling of the above exception, another exception occurred:

Traceback (most recent call last):
  File "/home/quarjo/pollproject/env/lib/python3.12/site-packages/django/core/handlers/exception.py", line 55, in inner
    response = get_response(request)
               ^^^^^^^^^^^^^^^^^^^^^
  File "/home/quarjo/pollproject/env/lib/python3.12/site-packages/django/core/handlers/base.py", line 197, in _get_response
    response = wrapped_callback(request, *callback_args, **callback_kwargs)
               ^^^^^^^^^^^^^^^^^^^^^^^^^^^^^^^^^^^^^^^^^^^^^^^^^^^^^^^^^^^^
  File "/home/quarjo/pollproject/env/lib/python3.12/site-packages/django/views/decorators/csrf.py", line 65, in _view_wrapper
    return view_func(request, *args, **kwargs)
           ^^^^^^^^^^^^^^^^^^^^^^^^^^^^^^^^^^^
  File "/home/quarjo/pollproject/env/lib/python3.12/site-packages/django/views/generic/base.py", line 104, in view
    return self.dispatch(request, *args, **kwargs)
           ^^^^^^^^^^^^^^^^^^^^^^^^^^^^^^^^^^^^^^^
  File "/home/quarjo/pollproject/env/lib/python3.12/site-packages/rest_framework/views.py", line 509, in dispatch
    response = self.handle_exception(exc)
               ^^^^^^^^^^^^^^^^^^^^^^^^^^
  File "/home/quarjo/pollproject/env/lib/python3.12/site-packages/rest_framework/views.py", line 469, in handle_exception
    self.raise_uncaught_exception(exc)
  File "/home/quarjo/pollproject/env/lib/python3.12/site-packages/rest_framework/views.py", line 480, in raise_uncaught_exception
    raise exc
  File "/home/quarjo/pollproject/env/lib/python3.12/site-packages/rest_framework/views.py", line 506, in dispatch
    response = handler(request, *args, **kwargs)
               ^^^^^^^^^^^^^^^^^^^^^^^^^^^^^^^^^
  File "/home/quarjo/pollproject/poll/views.py", line 151, in get
    contestants = poll.contestants.values(
                  ^^^^^^^^^^^^^^^^^^^^^^^^
  File "/home/quarjo/pollproject/env/lib/python3.12/site-packages/django/db/models/manager.py", line 87, in manager_method
    return getattr(self.get_queryset(), name)(*args, **kwargs)
           ^^^^^^^^^^^^^^^^^^^^^^^^^^^^^^^^^^^^^^^^^^^^^^^^^^^
  File "/home/quarjo/pollproject/env/lib/python3.12/site-packages/django/db/models/query.py", line 1360, in values
    clone = self._values(*fields, **expressions)
            ^^^^^^^^^^^^^^^^^^^^^^^^^^^^^^^^^^^^
  File "/home/quarjo/pollproject/env/lib/python3.12/site-packages/django/db/models/query.py", line 1355, in _values
    clone.query.set_values(fields)
  File "/home/quarjo/pollproject/env/lib/python3.12/site-packages/django/db/models/sql/query.py", line 2500, in set_values
    self.add_fields(field_names, True)
  File "/home/quarjo/pollproject/env/lib/python3.12/site-packages/django/db/models/sql/query.py", line 2223, in add_fields
    raise FieldError(
django.core.exceptions.FieldError: Cannot resolve keyword 'award' into field. Choices are: category, id, image, name, nominee_code, poll, poll_id, votes
"GET /polls/6/ HTTP/1.1" 500 21591
Internal Server Error: /polls/6/
Traceback (most recent call last):
  File "/home/quarjo/pollproject/env/lib/python3.12/site-packages/django/db/models/sql/query.py", line 2195, in add_fields
    join_info = self.setup_joins(
                ^^^^^^^^^^^^^^^^^
  File "/home/quarjo/pollproject/env/lib/python3.12/site-packages/django/db/models/sql/query.py", line 1863, in setup_joins
    path, final_field, targets, rest = self.names_to_path(
                                       ^^^^^^^^^^^^^^^^^^^
  File "/home/quarjo/pollproject/env/lib/python3.12/site-packages/django/db/models/sql/query.py", line 1768, in names_to_path
    raise FieldError(
django.core.exceptions.FieldError: Cannot resolve keyword 'award' into field. Choices are: category, id, image, name, nominee_code, poll, poll_id, votes

During handling of the above exception, another exception occurred:

Traceback (most recent call last):
  File "/home/quarjo/pollproject/env/lib/python3.12/site-packages/django/core/handlers/exception.py", line 55, in inner
    response = get_response(request)
               ^^^^^^^^^^^^^^^^^^^^^
  File "/home/quarjo/pollproject/env/lib/python3.12/site-packages/django/core/handlers/base.py", line 197, in _get_response
    response = wrapped_callback(request, *callback_args, **callback_kwargs)
               ^^^^^^^^^^^^^^^^^^^^^^^^^^^^^^^^^^^^^^^^^^^^^^^^^^^^^^^^^^^^
  File "/home/quarjo/pollproject/env/lib/python3.12/site-packages/django/views/decorators/csrf.py", line 65, in _view_wrapper
    return view_func(request, *args, **kwargs)
           ^^^^^^^^^^^^^^^^^^^^^^^^^^^^^^^^^^^
  File "/home/quarjo/pollproject/env/lib/python3.12/site-packages/django/views/generic/base.py", line 104, in view
    return self.dispatch(request, *args, **kwargs)
           ^^^^^^^^^^^^^^^^^^^^^^^^^^^^^^^^^^^^^^^
  File "/home/quarjo/pollproject/env/lib/python3.12/site-packages/rest_framework/views.py", line 509, in dispatch
    response = self.handle_exception(exc)
               ^^^^^^^^^^^^^^^^^^^^^^^^^^
  File "/home/quarjo/pollproject/env/lib/python3.12/site-packages/rest_framework/views.py", line 469, in handle_exception
    self.raise_uncaught_exception(exc)
  File "/home/quarjo/pollproject/env/lib/python3.12/site-packages/rest_framework/views.py", line 480, in raise_uncaught_exception
    raise exc
  File "/home/quarjo/pollproject/env/lib/python3.12/site-packages/rest_framework/views.py", line 506, in dispatch
    response = handler(request, *args, **kwargs)
               ^^^^^^^^^^^^^^^^^^^^^^^^^^^^^^^^^
  File "/home/quarjo/pollproject/poll/views.py", line 151, in get
    contestants = poll.contestants.values(
                  ^^^^^^^^^^^^^^^^^^^^^^^^
  File "/home/quarjo/pollproject/env/lib/python3.12/site-packages/django/db/models/manager.py", line 87, in manager_method
    return getattr(self.get_queryset(), name)(*args, **kwargs)
           ^^^^^^^^^^^^^^^^^^^^^^^^^^^^^^^^^^^^^^^^^^^^^^^^^^^
  File "/home/quarjo/pollproject/env/lib/python3.12/site-packages/django/db/models/query.py", line 1360, in values
    clone = self._values(*fields, **expressions)
            ^^^^^^^^^^^^^^^^^^^^^^^^^^^^^^^^^^^^
  File "/home/quarjo/pollproject/env/lib/python3.12/site-packages/django/db/models/query.py", line 1355, in _values
    clone.query.set_values(fields)
  File "/home/quarjo/pollproject/env/lib/python3.12/site-packages/django/db/models/sql/query.py", line 2500, in set_values
    self.add_fields(field_names, True)
  File "/home/quarjo/pollproject/env/lib/python3.12/site-packages/django/db/models/sql/query.py", line 2223, in add_fields
    raise FieldError(
django.core.exceptions.FieldError: Cannot resolve keyword 'award' into field. Choices are: category, id, image, name, nominee_code, poll, poll_id, votes
"GET /polls/6/ HTTP/1.1" 500 21591
Invalid HTTP_HOST header: '958c-102-176-94-100.ngrok-free.app'. You may need to add '958c-102-176-94-100.ngrok-free.app' to ALLOWED_HOSTS.
Traceback (most recent call last):
  File "/home/quarjo/pollproject/env/lib/python3.12/site-packages/django/core/handlers/exception.py", line 55, in inner
    response = get_response(request)
               ^^^^^^^^^^^^^^^^^^^^^
  File "/home/quarjo/pollproject/env/lib/python3.12/site-packages/django/utils/deprecation.py", line 128, in __call__
    response = self.process_request(request)
               ^^^^^^^^^^^^^^^^^^^^^^^^^^^^^
  File "/home/quarjo/pollproject/env/lib/python3.12/site-packages/django/middleware/common.py", line 48, in process_request
    host = request.get_host()
           ^^^^^^^^^^^^^^^^^^
  File "/home/quarjo/pollproject/env/lib/python3.12/site-packages/django/http/request.py", line 151, in get_host
    raise DisallowedHost(msg)
django.core.exceptions.DisallowedHost: Invalid HTTP_HOST header: '958c-102-176-94-100.ngrok-free.app'. You may need to add '958c-102-176-94-100.ngrok-free.app' to ALLOWED_HOSTS.
Invalid HTTP_HOST header: '958c-102-176-94-100.ngrok-free.app'. You may need to add '958c-102-176-94-100.ngrok-free.app' to ALLOWED_HOSTS.
Traceback (most recent call last):
  File "/home/quarjo/pollproject/env/lib/python3.12/site-packages/django/core/handlers/exception.py", line 55, in inner
    response = get_response(request)
               ^^^^^^^^^^^^^^^^^^^^^
  File "/home/quarjo/pollproject/env/lib/python3.12/site-packages/django/utils/deprecation.py", line 128, in __call__
    response = self.process_request(request)
               ^^^^^^^^^^^^^^^^^^^^^^^^^^^^^
  File "/home/quarjo/pollproject/env/lib/python3.12/site-packages/django/middleware/common.py", line 48, in process_request
    host = request.get_host()
           ^^^^^^^^^^^^^^^^^^
  File "/home/quarjo/pollproject/env/lib/python3.12/site-packages/django/http/request.py", line 151, in get_host
    raise DisallowedHost(msg)
django.core.exceptions.DisallowedHost: Invalid HTTP_HOST header: '958c-102-176-94-100.ngrok-free.app'. You may need to add '958c-102-176-94-100.ngrok-free.app' to ALLOWED_HOSTS.
Invalid HTTP_HOST header: '958c-102-176-94-100.ngrok-free.app'. You may need to add '958c-102-176-94-100.ngrok-free.app' to ALLOWED_HOSTS.
Traceback (most recent call last):
  File "/home/quarjo/pollproject/env/lib/python3.12/site-packages/django/core/handlers/exception.py", line 55, in inner
    response = get_response(request)
               ^^^^^^^^^^^^^^^^^^^^^
  File "/home/quarjo/pollproject/env/lib/python3.12/site-packages/django/utils/deprecation.py", line 128, in __call__
    response = self.process_request(request)
               ^^^^^^^^^^^^^^^^^^^^^^^^^^^^^
  File "/home/quarjo/pollproject/env/lib/python3.12/site-packages/django/middleware/common.py", line 48, in process_request
    host = request.get_host()
           ^^^^^^^^^^^^^^^^^^
  File "/home/quarjo/pollproject/env/lib/python3.12/site-packages/django/http/request.py", line 151, in get_host
    raise DisallowedHost(msg)
django.core.exceptions.DisallowedHost: Invalid HTTP_HOST header: '958c-102-176-94-100.ngrok-free.app'. You may need to add '958c-102-176-94-100.ngrok-free.app' to ALLOWED_HOSTS.
Invalid HTTP_HOST header: '958c-102-176-94-100.ngrok-free.app'. You may need to add '958c-102-176-94-100.ngrok-free.app' to ALLOWED_HOSTS.
Traceback (most recent call last):
  File "/home/quarjo/pollproject/env/lib/python3.12/site-packages/django/core/handlers/exception.py", line 55, in inner
    response = get_response(request)
               ^^^^^^^^^^^^^^^^^^^^^
  File "/home/quarjo/pollproject/env/lib/python3.12/site-packages/django/utils/deprecation.py", line 128, in __call__
    response = self.process_request(request)
               ^^^^^^^^^^^^^^^^^^^^^^^^^^^^^
  File "/home/quarjo/pollproject/env/lib/python3.12/site-packages/django/middleware/common.py", line 48, in process_request
    host = request.get_host()
           ^^^^^^^^^^^^^^^^^^
  File "/home/quarjo/pollproject/env/lib/python3.12/site-packages/django/http/request.py", line 151, in get_host
    raise DisallowedHost(msg)
django.core.exceptions.DisallowedHost: Invalid HTTP_HOST header: '958c-102-176-94-100.ngrok-free.app'. You may need to add '958c-102-176-94-100.ngrok-free.app' to ALLOWED_HOSTS.
Invalid HTTP_HOST header: '958c-102-176-94-100.ngrok-free.app'. You may need to add '958c-102-176-94-100.ngrok-free.app' to ALLOWED_HOSTS.
Traceback (most recent call last):
  File "/home/quarjo/pollproject/env/lib/python3.12/site-packages/django/core/handlers/exception.py", line 55, in inner
    response = get_response(request)
               ^^^^^^^^^^^^^^^^^^^^^
  File "/home/quarjo/pollproject/env/lib/python3.12/site-packages/django/utils/deprecation.py", line 128, in __call__
    response = self.process_request(request)
               ^^^^^^^^^^^^^^^^^^^^^^^^^^^^^
  File "/home/quarjo/pollproject/env/lib/python3.12/site-packages/django/middleware/common.py", line 48, in process_request
    host = request.get_host()
           ^^^^^^^^^^^^^^^^^^
  File "/home/quarjo/pollproject/env/lib/python3.12/site-packages/django/http/request.py", line 151, in get_host
    raise DisallowedHost(msg)
django.core.exceptions.DisallowedHost: Invalid HTTP_HOST header: '958c-102-176-94-100.ngrok-free.app'. You may need to add '958c-102-176-94-100.ngrok-free.app' to ALLOWED_HOSTS.
Invalid HTTP_HOST header: '958c-102-176-94-100.ngrok-free.app'. You may need to add '958c-102-176-94-100.ngrok-free.app' to ALLOWED_HOSTS.
Traceback (most recent call last):
  File "/home/quarjo/pollproject/env/lib/python3.12/site-packages/django/core/handlers/exception.py", line 55, in inner
    response = get_response(request)
               ^^^^^^^^^^^^^^^^^^^^^
  File "/home/quarjo/pollproject/env/lib/python3.12/site-packages/django/utils/deprecation.py", line 128, in __call__
    response = self.process_request(request)
               ^^^^^^^^^^^^^^^^^^^^^^^^^^^^^
  File "/home/quarjo/pollproject/env/lib/python3.12/site-packages/django/middleware/common.py", line 48, in process_request
    host = request.get_host()
           ^^^^^^^^^^^^^^^^^^
  File "/home/quarjo/pollproject/env/lib/python3.12/site-packages/django/http/request.py", line 151, in get_host
    raise DisallowedHost(msg)
django.core.exceptions.DisallowedHost: Invalid HTTP_HOST header: '958c-102-176-94-100.ngrok-free.app'. You may need to add '958c-102-176-94-100.ngrok-free.app' to ALLOWED_HOSTS.
Internal Server Error: /payment/verify/activate-24-9847f/
Internal Server Error: /payment/verify/activate-24-9847f/
Internal Server Error: /payment/verify/activate-24-9847f/
"GET /payment/verify/activate-24-9847f/ HTTP/1.1" 500 49
Internal Server Error: /payment/verify/activate-25-dfe0b/
"GET /payment/verify/activate-25-dfe0b/ HTTP/1.1" 500 49
Internal Server Error: /payment/verify/activate-25-dfe0b/
"GET /payment/verify/activate-25-dfe0b/ HTTP/1.1" 500 49
Internal Server Error: /payment/verify/activate-25-dfe0b/
"GET /payment/verify/activate-25-dfe0b/ HTTP/1.1" 500 49
Internal Server Error: /payment/verify/activate-25-dfe0b/
"GET /payment/verify/activate-25-dfe0b/ HTTP/1.1" 500 49
Internal Server Error: /payment/verify/activate-25-dfe0b/
"GET /payment/verify/activate-25-dfe0b/ HTTP/1.1" 500 49
Internal Server Error: /payment/verify/activate-26-1409c/
"GET /payment/verify/activate-26-1409c/ HTTP/1.1" 500 49
Internal Server Error: /payment/verify/activate-27-f709c/
"GET /payment/verify/activate-27-f709c/ HTTP/1.1" 500 49
Internal Server Error: /payment/poll/29/link/
Internal Server Error: /payment/poll/28/link/
Internal Server Error: /payment/poll/27/link/
Internal Server Error: /polls/27/contestants/create
Traceback (most recent call last):
  File "/home/quarjo/pollproject/env/lib/python3.12/site-packages/django/core/handlers/exception.py", line 55, in inner
    response = get_response(request)
               ^^^^^^^^^^^^^^^^^^^^^
  File "/home/quarjo/pollproject/env/lib/python3.12/site-packages/django/utils/deprecation.py", line 131, in __call__
    response = self.process_response(request, response)
               ^^^^^^^^^^^^^^^^^^^^^^^^^^^^^^^^^^^^^^^^
  File "/home/quarjo/pollproject/env/lib/python3.12/site-packages/django/middleware/common.py", line 108, in process_response
    return self.response_redirect_class(self.get_full_path_with_slash(request))
                                        ^^^^^^^^^^^^^^^^^^^^^^^^^^^^^^^^^^^^^^
  File "/home/quarjo/pollproject/env/lib/python3.12/site-packages/django/middleware/common.py", line 87, in get_full_path_with_slash
    raise RuntimeError(
RuntimeError: You called this URL via POST, but the URL doesn't end in a slash and you have APPEND_SLASH set. Django can't redirect to the slash URL while maintaining POST data. Change your form to point to localhost:8000/polls/27/contestants/create/ (note the trailing slash), or set APPEND_SLASH=False in your Django settings.
"POST /polls/27/contestants/create HTTP/1.1" 500 19571
Internal Server Error: /auth/reset/password/MQ/cir162-44504f4cb758f76d4fedb85a4b9fbf51/
Traceback (most recent call last):
  File "/home/quarjo/pollproject/env/lib/python3.12/site-packages/django/core/handlers/exception.py", line 55, in inner
    response = get_response(request)
               ^^^^^^^^^^^^^^^^^^^^^
  File "/home/quarjo/pollproject/env/lib/python3.12/site-packages/django/core/handlers/base.py", line 197, in _get_response
    response = wrapped_callback(request, *callback_args, **callback_kwargs)
               ^^^^^^^^^^^^^^^^^^^^^^^^^^^^^^^^^^^^^^^^^^^^^^^^^^^^^^^^^^^^
  File "/home/quarjo/pollproject/env/lib/python3.12/site-packages/django/views/decorators/csrf.py", line 65, in _view_wrapper
    return view_func(request, *args, **kwargs)
           ^^^^^^^^^^^^^^^^^^^^^^^^^^^^^^^^^^^
  File "/home/quarjo/pollproject/env/lib/python3.12/site-packages/django/views/generic/base.py", line 104, in view
    return self.dispatch(request, *args, **kwargs)
           ^^^^^^^^^^^^^^^^^^^^^^^^^^^^^^^^^^^^^^^
  File "/home/quarjo/pollproject/env/lib/python3.12/site-packages/rest_framework/views.py", line 511, in dispatch
    self.response = self.finalize_response(request, response, *args, **kwargs)
                    ^^^^^^^^^^^^^^^^^^^^^^^^^^^^^^^^^^^^^^^^^^^^^^^^^^^^^^^^^^
  File "/home/quarjo/pollproject/env/lib/python3.12/site-packages/rest_framework/views.py", line 423, in finalize_response
    assert isinstance(response, HttpResponseBase), (
           ^^^^^^^^^^^^^^^^^^^^^^^^^^^^^^^^^^^^^^
AssertionError: Expected a `Response`, `HttpResponse` or `StreamingHttpResponse` to be returned from the view, but received a `<class 'NoneType'>`
"POST /auth/reset/password/MQ/cir162-44504f4cb758f76d4fedb85a4b9fbf51/ HTTP/1.1" 500 19869
Internal Server Error: /auth/reset/password/
Traceback (most recent call last):
  File "/home/quarjo/pollproject/env/lib/python3.12/site-packages/django/core/handlers/exception.py", line 55, in inner
    response = get_response(request)
               ^^^^^^^^^^^^^^^^^^^^^
  File "/home/quarjo/pollproject/env/lib/python3.12/site-packages/django/core/handlers/base.py", line 197, in _get_response
    response = wrapped_callback(request, *callback_args, **callback_kwargs)
               ^^^^^^^^^^^^^^^^^^^^^^^^^^^^^^^^^^^^^^^^^^^^^^^^^^^^^^^^^^^^
  File "/home/quarjo/pollproject/env/lib/python3.12/site-packages/django/views/decorators/csrf.py", line 65, in _view_wrapper
    return view_func(request, *args, **kwargs)
           ^^^^^^^^^^^^^^^^^^^^^^^^^^^^^^^^^^^
  File "/home/quarjo/pollproject/env/lib/python3.12/site-packages/django/views/generic/base.py", line 104, in view
    return self.dispatch(request, *args, **kwargs)
           ^^^^^^^^^^^^^^^^^^^^^^^^^^^^^^^^^^^^^^^
  File "/home/quarjo/pollproject/env/lib/python3.12/site-packages/rest_framework/views.py", line 509, in dispatch
    response = self.handle_exception(exc)
               ^^^^^^^^^^^^^^^^^^^^^^^^^^
  File "/home/quarjo/pollproject/env/lib/python3.12/site-packages/rest_framework/views.py", line 469, in handle_exception
    self.raise_uncaught_exception(exc)
  File "/home/quarjo/pollproject/env/lib/python3.12/site-packages/rest_framework/views.py", line 480, in raise_uncaught_exception
    raise exc
  File "/home/quarjo/pollproject/env/lib/python3.12/site-packages/rest_framework/views.py", line 506, in dispatch
    response = handler(request, *args, **kwargs)
               ^^^^^^^^^^^^^^^^^^^^^^^^^^^^^^^^^
  File "/home/quarjo/pollproject/authentication/views.py", line 108, in post
    send_mail(
  File "/home/quarjo/pollproject/env/lib/python3.12/site-packages/django/core/mail/__init__.py", line 88, in send_mail
    return mail.send()
           ^^^^^^^^^^^
  File "/home/quarjo/pollproject/env/lib/python3.12/site-packages/django/core/mail/message.py", line 301, in send
    return self.get_connection(fail_silently).send_messages([self])
           ^^^^^^^^^^^^^^^^^^^^^^^^^^^^^^^^^^^^^^^^^^^^^^^^^^^^^^^^
  File "/home/quarjo/pollproject/env/lib/python3.12/site-packages/django/core/mail/backends/smtp.py", line 128, in send_messages
    new_conn_created = self.open()
                       ^^^^^^^^^^^
  File "/home/quarjo/pollproject/env/lib/python3.12/site-packages/django/core/mail/backends/smtp.py", line 86, in open
    self.connection = self.connection_class(
                      ^^^^^^^^^^^^^^^^^^^^^^
  File "/usr/lib/python3.12/smtplib.py", line 258, in __init__
    raise SMTPConnectError(code, msg)
smtplib.SMTPConnectError: (421, b'Service not available')
"POST /auth/reset/password/ HTTP/1.1" 500 22302
Internal Server Error: /auth/reset/password/
Traceback (most recent call last):
  File "/home/quarjo/pollproject/env/lib/python3.12/site-packages/django/core/handlers/exception.py", line 55, in inner
    response = get_response(request)
               ^^^^^^^^^^^^^^^^^^^^^
  File "/home/quarjo/pollproject/env/lib/python3.12/site-packages/django/core/handlers/base.py", line 197, in _get_response
    response = wrapped_callback(request, *callback_args, **callback_kwargs)
               ^^^^^^^^^^^^^^^^^^^^^^^^^^^^^^^^^^^^^^^^^^^^^^^^^^^^^^^^^^^^
  File "/home/quarjo/pollproject/env/lib/python3.12/site-packages/django/views/decorators/csrf.py", line 65, in _view_wrapper
    return view_func(request, *args, **kwargs)
           ^^^^^^^^^^^^^^^^^^^^^^^^^^^^^^^^^^^
  File "/home/quarjo/pollproject/env/lib/python3.12/site-packages/django/views/generic/base.py", line 104, in view
    return self.dispatch(request, *args, **kwargs)
           ^^^^^^^^^^^^^^^^^^^^^^^^^^^^^^^^^^^^^^^
  File "/home/quarjo/pollproject/env/lib/python3.12/site-packages/rest_framework/views.py", line 509, in dispatch
    response = self.handle_exception(exc)
               ^^^^^^^^^^^^^^^^^^^^^^^^^^
  File "/home/quarjo/pollproject/env/lib/python3.12/site-packages/rest_framework/views.py", line 469, in handle_exception
    self.raise_uncaught_exception(exc)
  File "/home/quarjo/pollproject/env/lib/python3.12/site-packages/rest_framework/views.py", line 480, in raise_uncaught_exception
    raise exc
  File "/home/quarjo/pollproject/env/lib/python3.12/site-packages/rest_framework/views.py", line 506, in dispatch
    response = handler(request, *args, **kwargs)
               ^^^^^^^^^^^^^^^^^^^^^^^^^^^^^^^^^
  File "/home/quarjo/pollproject/authentication/views.py", line 108, in post
    send_mail(
  File "/home/quarjo/pollproject/env/lib/python3.12/site-packages/django/core/mail/__init__.py", line 88, in send_mail
    return mail.send()
           ^^^^^^^^^^^
  File "/home/quarjo/pollproject/env/lib/python3.12/site-packages/django/core/mail/message.py", line 301, in send
    return self.get_connection(fail_silently).send_messages([self])
           ^^^^^^^^^^^^^^^^^^^^^^^^^^^^^^^^^^^^^^^^^^^^^^^^^^^^^^^^
  File "/home/quarjo/pollproject/env/lib/python3.12/site-packages/django/core/mail/backends/smtp.py", line 128, in send_messages
    new_conn_created = self.open()
                       ^^^^^^^^^^^
  File "/home/quarjo/pollproject/env/lib/python3.12/site-packages/django/core/mail/backends/smtp.py", line 86, in open
    self.connection = self.connection_class(
                      ^^^^^^^^^^^^^^^^^^^^^^
  File "/usr/lib/python3.12/smtplib.py", line 258, in __init__
    raise SMTPConnectError(code, msg)
smtplib.SMTPConnectError: (421, b'Service not available')
"POST /auth/reset/password/ HTTP/1.1" 500 22304
Internal Server Error: /vote/voter-pay/31/
Traceback (most recent call last):
  File "/home/quarjo/pollproject/env/lib/python3.12/site-packages/urllib3/connection.py", line 199, in _new_conn
    sock = connection.create_connection(
           ^^^^^^^^^^^^^^^^^^^^^^^^^^^^^
  File "/home/quarjo/pollproject/env/lib/python3.12/site-packages/urllib3/util/connection.py", line 60, in create_connection
    for res in socket.getaddrinfo(host, port, family, socket.SOCK_STREAM):
               ^^^^^^^^^^^^^^^^^^^^^^^^^^^^^^^^^^^^^^^^^^^^^^^^^^^^^^^^^^
  File "/usr/lib/python3.12/socket.py", line 976, in getaddrinfo
    for res in _socket.getaddrinfo(host, port, family, type, proto, flags):
               ^^^^^^^^^^^^^^^^^^^^^^^^^^^^^^^^^^^^^^^^^^^^^^^^^^^^^^^^^^^
socket.gaierror: [Errno -3] Temporary failure in name resolution

The above exception was the direct cause of the following exception:

Traceback (most recent call last):
  File "/home/quarjo/pollproject/env/lib/python3.12/site-packages/urllib3/connectionpool.py", line 789, in urlopen
    response = self._make_request(
               ^^^^^^^^^^^^^^^^^^^
  File "/home/quarjo/pollproject/env/lib/python3.12/site-packages/urllib3/connectionpool.py", line 490, in _make_request
    raise new_e
  File "/home/quarjo/pollproject/env/lib/python3.12/site-packages/urllib3/connectionpool.py", line 466, in _make_request
    self._validate_conn(conn)
  File "/home/quarjo/pollproject/env/lib/python3.12/site-packages/urllib3/connectionpool.py", line 1095, in _validate_conn
    conn.connect()
  File "/home/quarjo/pollproject/env/lib/python3.12/site-packages/urllib3/connection.py", line 693, in connect
    self.sock = sock = self._new_conn()
                       ^^^^^^^^^^^^^^^^
  File "/home/quarjo/pollproject/env/lib/python3.12/site-packages/urllib3/connection.py", line 206, in _new_conn
    raise NameResolutionError(self.host, self, e) from e
urllib3.exceptions.NameResolutionError: <urllib3.connection.HTTPSConnection object at 0x7fa652526180>: Failed to resolve 'api.paystack.co' ([Errno -3] Temporary failure in name resolution)

The above exception was the direct cause of the following exception:

Traceback (most recent call last):
  File "/home/quarjo/pollproject/env/lib/python3.12/site-packages/requests/adapters.py", line 667, in send
    resp = conn.urlopen(
           ^^^^^^^^^^^^^
  File "/home/quarjo/pollproject/env/lib/python3.12/site-packages/urllib3/connectionpool.py", line 843, in urlopen
    retries = retries.increment(
              ^^^^^^^^^^^^^^^^^^
  File "/home/quarjo/pollproject/env/lib/python3.12/site-packages/urllib3/util/retry.py", line 519, in increment
    raise MaxRetryError(_pool, url, reason) from reason  # type: ignore[arg-type]
    ^^^^^^^^^^^^^^^^^^^^^^^^^^^^^^^^^^^^^^^^^^^^^^^^^^^
urllib3.exceptions.MaxRetryError: HTTPSConnectionPool(host='api.paystack.co', port=443): Max retries exceeded with url: /transaction/initialize (Caused by NameResolutionError("<urllib3.connection.HTTPSConnection object at 0x7fa652526180>: Failed to resolve 'api.paystack.co' ([Errno -3] Temporary failure in name resolution)"))

During handling of the above exception, another exception occurred:

Traceback (most recent call last):
  File "/home/quarjo/pollproject/env/lib/python3.12/site-packages/django/core/handlers/exception.py", line 55, in inner
    response = get_response(request)
               ^^^^^^^^^^^^^^^^^^^^^
  File "/home/quarjo/pollproject/env/lib/python3.12/site-packages/django/core/handlers/base.py", line 197, in _get_response
    response = wrapped_callback(request, *callback_args, **callback_kwargs)
               ^^^^^^^^^^^^^^^^^^^^^^^^^^^^^^^^^^^^^^^^^^^^^^^^^^^^^^^^^^^^
  File "/home/quarjo/pollproject/env/lib/python3.12/site-packages/django/views/decorators/csrf.py", line 65, in _view_wrapper
    return view_func(request, *args, **kwargs)
           ^^^^^^^^^^^^^^^^^^^^^^^^^^^^^^^^^^^
  File "/home/quarjo/pollproject/env/lib/python3.12/site-packages/django/views/generic/base.py", line 104, in view
    return self.dispatch(request, *args, **kwargs)
           ^^^^^^^^^^^^^^^^^^^^^^^^^^^^^^^^^^^^^^^
  File "/home/quarjo/pollproject/env/lib/python3.12/site-packages/rest_framework/views.py", line 509, in dispatch
    response = self.handle_exception(exc)
               ^^^^^^^^^^^^^^^^^^^^^^^^^^
  File "/home/quarjo/pollproject/env/lib/python3.12/site-packages/rest_framework/views.py", line 469, in handle_exception
    self.raise_uncaught_exception(exc)
  File "/home/quarjo/pollproject/env/lib/python3.12/site-packages/rest_framework/views.py", line 480, in raise_uncaught_exception
    raise exc
  File "/home/quarjo/pollproject/env/lib/python3.12/site-packages/rest_framework/views.py", line 506, in dispatch
    response = handler(request, *args, **kwargs)
               ^^^^^^^^^^^^^^^^^^^^^^^^^^^^^^^^^
  File "/home/quarjo/pollproject/vote/views.py", line 106, in post
    payment_link = self.generate_payment_link(
                   ^^^^^^^^^^^^^^^^^^^^^^^^^^^
  File "/home/quarjo/pollproject/vote/views.py", line 135, in generate_payment_link
    response = requests.post(url, json=data, headers=headers)
               ^^^^^^^^^^^^^^^^^^^^^^^^^^^^^^^^^^^^^^^^^^^^^^
  File "/home/quarjo/pollproject/env/lib/python3.12/site-packages/requests/api.py", line 115, in post
    return request("post", url, data=data, json=json, **kwargs)
           ^^^^^^^^^^^^^^^^^^^^^^^^^^^^^^^^^^^^^^^^^^^^^^^^^^^^
  File "/home/quarjo/pollproject/env/lib/python3.12/site-packages/requests/api.py", line 59, in request
    return session.request(method=method, url=url, **kwargs)
           ^^^^^^^^^^^^^^^^^^^^^^^^^^^^^^^^^^^^^^^^^^^^^^^^^
  File "/home/quarjo/pollproject/env/lib/python3.12/site-packages/requests/sessions.py", line 589, in request
    resp = self.send(prep, **send_kwargs)
           ^^^^^^^^^^^^^^^^^^^^^^^^^^^^^^
  File "/home/quarjo/pollproject/env/lib/python3.12/site-packages/requests/sessions.py", line 703, in send
    r = adapter.send(request, **kwargs)
        ^^^^^^^^^^^^^^^^^^^^^^^^^^^^^^^
  File "/home/quarjo/pollproject/env/lib/python3.12/site-packages/requests/adapters.py", line 700, in send
    raise ConnectionError(e, request=request)
requests.exceptions.ConnectionError: HTTPSConnectionPool(host='api.paystack.co', port=443): Max retries exceeded with url: /transaction/initialize (Caused by NameResolutionError("<urllib3.connection.HTTPSConnection object at 0x7fa652526180>: Failed to resolve 'api.paystack.co' ([Errno -3] Temporary failure in name resolution)"))
"POST /vote/voter-pay/31/ HTTP/1.1" 500 26404
